<?xml version="1.0"?>
<!--
 Software License Agreement (BSD License)
 Copyright © 2022 belongs to Shadow Robot Company Ltd.
 All rights reserved.
 Redistribution and use in source and binary forms, with or without modification,
 are permitted provided that the following conditions are met:
   1. Redistributions of source code must retain the above copyright notice,
      this list of conditions and the following disclaimer.
   2. Redistributions in binary form must reproduce the above copyright notice,
      this list of conditions and the following disclaimer in the documentation
      and/or other materials provided with the distribution.
   3. Neither the name of Shadow Robot Company Ltd nor the names of its contributors
      may be used to endorse or promote products derived from this software without
      specific prior written permission.
 This software is provided by Shadow Robot Company Ltd "as is" and any express
 or implied warranties, including, but not limited to, the implied warranties of
 merchantability and fitness for a particular purpose are disclaimed. In no event
 shall the copyright holder be liable for any direct, indirect, incidental, special,
 exemplary, or consequential damages (including, but not limited to, procurement of
 substitute goods or services; loss of use, data, or profits; or business interruption)
 however caused and on any theory of liability, whether in contract, strict liability,
 or tort (including negligence or otherwise) arising in any way out of the use of this
 software, even if advised of the possibility of such damage.
-->

<robot xmlns:xacro="http://www.ros.org/wiki/xacro"
       xmlns:sensor="http://playerstage.sourceforge.net/gazebo/xmlschema/#sensor"
       xmlns:controller="http://playerstage.sourceforge.net/gazebo/xmlschema/#controller"
       xmlns:joint="http://playerstage.sourceforge.net/gazebo/xmlschema/#slider"
       xmlns:interface="http://playerstage.sourceforge.net/gazebo/xmlschema/#interface"
       xmlns:body="http://playerstage.sourceforge.net/gazebo/xmlschema/#body"
       xmlns:geom="http://playerstage.sourceforge.net/gazebo/xmlschema/#geom">

  <xacro:include filename="$(find sr_description)/hand/xacro/thumb/thhub.gazebo.xacro" />
  <xacro:include filename="$(find sr_description)/hand/xacro/thumb/thhub.transmission.xacro" />

  <xacro:macro name="thhub" params="prefix:=^ parent:=^ is_lite">
    <link name="${prefix}thhub">
      <inertial>
        <mass value="0.005" />
        <origin xyz="0 0 0" rpy="0 0 0" />
        <inertia ixx="0.000001" ixy="0.0" ixz="0.0" iyy="0.000001" iyz="0.0" izz="0.0000003" />
      </inertial>
      <visual>
        <origin xyz="0 0 0" rpy="0 0 0" />
        <geometry name="${prefix}thhub_visual">
          <box size="0.001 0.001 0.001" />
        </geometry>
        <material name="shadow_thhub_material">
          <color rgba="0.7 0.7 0.7 1.0" />
        </material>
      </visual>
      <collision>
        <origin xyz="0 0 0" rpy="0 0 0" />
        <geometry name="${prefix}thhub_collision_geom">
          <sphere radius="0.010" />
        </geometry>
      </collision>
    </link>
    <xacro:if value="${is_lite}">
      <joint name="${prefix}THJ3" type="fixed">
        <parent link="${parent}" />
        <child link="${prefix}thhub" />
        <origin xyz="0 0 0.038" rpy="0 0 0" />
        <axis xyz="1 0 0" />
      </joint>
    </xacro:if>
    <xacro:unless value="${is_lite}">
      <joint name="${prefix}THJ3" type="revolute">
        <parent link="${parent}" />
        <child link="${prefix}thhub" />
        <origin xyz="0 0 0.038" rpy="0 0 0" />
        <axis xyz="0 ${reflect} 0" />
        <limit lower="${-12/180*pi}" upper="${12/180*pi}" effort="2.0" velocity="4.0" />
        <dynamics damping="0.2" />
      </joint>
      <gazebo reference="${prefix}THJ3">
        <provideFeedback>1</provideFeedback>
        <implicitSpringDamper>1</implicitSpringDamper>
      </gazebo>
    </xacro:unless>
    <!-- extensions -->
    <xacro:unless value="${is_lite}">
      <xacro:thhub_transmission />
    </xacro:unless>
    <xacro:thhub_gazebo />
  </xacro:macro>
</robot>
