<?xml version="1.0" ?>
<!-- =================================================================================== -->
<!-- |    This document was autogenerated by xacro from r300_robot.xacro               | -->
<!-- |    EDITING THIS FILE BY HAND IS NOT RECOMMENDED                                 | -->
<!-- =================================================================================== -->
<robot name="r300">
  <link name="left_arm_base">
    <visual>
      <geometry>
        <mesh filename="./meshes/xmate3/meshes/visual/xmate3_base.stl" scale="0.001 0.001 0.001"/>
      </geometry>
      <origin rpy="0 0 0" xyz="0.0 0.0 0.0"/>
      <material name="left_white"/>
    </visual>
    <inertial>
      <mass value="5.48267"/>
      <inertia ixx="0.056" ixy="0" ixz="0" iyy="0.066" iyz="0" izz="0.035"/>
      <origin rpy="0 0 0" xyz="-0.0183 0 0.067"/>
    </inertial>
    <collision>
      <geometry>
        <mesh filename="./meshes/xmate3/meshes/collision/xmate3_base.stl" scale="0.001 0.001 0.001"/>
      </geometry>
      <origin rpy="0 0 0" xyz="0.0 0.0 0.0"/>
    </collision>
  </link>
  <joint name="left_arm_joint_1" type="revolute">
    <parent link="left_arm_base"/>
    <child link="left_arm_link1"/>
    <limit effort="300" lower="-3.0527" upper="3.0527" velocity="10"/>
    <axis xyz="0 0 1"/>
    <origin rpy="0 0 0" xyz="0 0 0"/>
  </joint>
  <transmission name="left_tran1">
    <type>transmission_interface/SimpleTransmission</type>
    <joint name="left_arm_joint_1">
      <hardwareInterface>EffortJointInterface</hardwareInterface>
    </joint>
    <actuator name="motor1">
      <hardwareInterface>EffortJointInterface</hardwareInterface>
      <mechanicalReduction>1</mechanicalReduction>
    </actuator>
  </transmission>
  <!--link 1-->
  <link name="left_arm_link1">
    <visual>
      <geometry>
        <mesh filename="./meshes/xmate3/meshes/visual/xmate3_link1.stl" scale="0.001 0.001 0.001"/>
      </geometry>
      <origin rpy="0 0 0" xyz="0 0 0"/>
      <material name="left_white"/>
    </visual>
    <inertial>
      <mass value="3.37289"/>
      <inertia ixx="0.314" ixy="0" ixz="0" iyy="0.310" iyz="0" izz="0.01"/>
      <origin rpy="0 0 0" xyz="0 -0.023 0.295"/>
    </inertial>
    <collision>
      <geometry>
        <mesh filename="./meshes/xmate3/meshes/collision/xmate3_link1.stl" scale="0.001 0.001 0.001"/>
      </geometry>
      <origin rpy="0 0 0" xyz="0 0 0"/>
    </collision>
  </link>
  <joint name="left_arm_joint_2" type="revolute">
    <parent link="left_arm_link1"/>
    <child link="left_arm_link2"/>
    <limit effort="300" lower="-2.0933" upper="2.0933" velocity="10"/>
    <axis xyz="0 1 0"/>
    <origin rpy="0 0 0" xyz="0 0 0.34260487"/>
  </joint>
  <transmission name="left_tran2">
    <type>transmission_interface/SimpleTransmission</type>
    <joint name="left_arm_joint_2">
      <hardwareInterface>EffortJointInterface</hardwareInterface>
    </joint>
    <actuator name="motor2">
      <hardwareInterface>EffortJointInterface</hardwareInterface>
      <mechanicalReduction>1</mechanicalReduction>
    </actuator>
  </transmission>
  <!--link 2-->
  <link name="left_arm_link2">
    <visual>
      <geometry>
        <mesh filename="./meshes/xmate3/meshes/visual/xmate3_link2.stl" scale="0.001 0.001 0.001"/>
      </geometry>
      <origin rpy="0 0 0" xyz="0 0 0.0"/>
      <material name="left_white"/>
    </visual>
    <inertial>
      <mass value="3.74765"/>
      <inertia ixx="0.074" ixy="0" ixz="0" iyy="0.067" iyz="0" izz="0.014"/>
      <origin rpy="0 0 0" xyz="0 0.032 0.095"/>
    </inertial>
    <collision>
      <geometry>
        <mesh filename="./meshes/xmate3/meshes/collision/xmate3_link2.stl" scale="0.001 0.001 0.001"/>
      </geometry>
      <origin rpy="0 0 0" xyz="0 0 0.0"/>
    </collision>
  </link>
  <joint name="left_arm_joint_3" type="revolute">
    <parent link="left_arm_link2"/>
    <child link="left_arm_link3"/>
    <limit effort="300" lower="-3.0527" upper="3.0527" velocity="10"/>
    <axis xyz="0 0 1"/>
    <origin rpy="0 0 0" xyz="0 0 0.23743878"/>
  </joint>
  <transmission name="left_tran3">
    <type>transmission_interface/SimpleTransmission</type>
    <joint name="left_arm_joint_3">
      <hardwareInterface>EffortJointInterface</hardwareInterface>
    </joint>
    <actuator name="motor3">
      <hardwareInterface>EffortJointInterface</hardwareInterface>
      <mechanicalReduction>1</mechanicalReduction>
    </actuator>
  </transmission>
  <!--${nameofManipulator}_link 3-->
  <link name="left_arm_link3">
    <visual>
      <geometry>
        <mesh filename="./meshes/xmate3/meshes/visual/xmate3_link3.stl" scale="0.001 0.001 0.001"/>
      </geometry>
      <origin rpy="0 0 0" xyz="0 0 0.15549959"/>
      <material name="left_white"/>
    </visual>
    <inertial>
      <mass value="3.38216"/>
      <inertia ixx="0.028" ixy="0" ixz="0" iyy="0.025" iyz="0" izz="0.01"/>
      <origin rpy="0 0 0" xyz="0 -0.023 -0.048"/>
    </inertial>
    <collision>
      <geometry>
        <mesh filename="./meshes/xmate3/meshes/collision/xmate3_link3.stl" scale="0.001 0.001 0.001"/>
      </geometry>
      <origin rpy="0 0 0" xyz="0 0 0.15549959"/>
    </collision>
  </link>
  <joint name="left_arm_joint_4" type="revolute">
    <parent link="left_arm_link3"/>
    <child link="left_arm_link4"/>
    <limit effort="300" lower="-2.0933" upper="2.0933" velocity="10"/>
    <!--     lower="-2.79" upper="2.79" -->
    <axis xyz="0 1 0"/>
    <!--     <origin rpy="0 0 0" xyz="0.585 0.0 0.035"/> -->
    <origin rpy="0 0 0" xyz="0 0 0.15549959"/>
  </joint>
  <transmission name="left_tran4">
    <type>transmission_interface/SimpleTransmission</type>
    <joint name="left_arm_joint_4">
      <hardwareInterface>EffortJointInterface</hardwareInterface>
    </joint>
    <actuator name="motor4">
      <hardwareInterface>EffortJointInterface</hardwareInterface>
      <mechanicalReduction>1</mechanicalReduction>
    </actuator>
  </transmission>
  <!--link 4-->
  <link name="left_arm_link4">
    <visual>
      <geometry>
        <mesh filename="./meshes/xmate3/meshes/visual/xmate3_link4.stl" scale=".001 0.001 0.001"/>
      </geometry>
      <origin rpy="0 0 0" xyz="0.0 0.0 0.0"/>
      <material name="left_white"/>
    </visual>
    <inertial>
      <mass value="3.21031"/>
      <inertia ixx="0.027" ixy="0" ixz="0" iyy="0.024" iyz="0" izz="0.007"/>
      <origin rpy="0 0 0" xyz="0 0.037 0.075"/>
    </inertial>
    <collision>
      <geometry>
        <mesh filename="./meshes/xmate3/meshes/collision/xmate3_link4.stl" scale="0.001 0.001 0.001"/>
      </geometry>
      <origin rpy="0 0 0" xyz="0.0 0.0 0.0"/>
    </collision>
  </link>
  <joint name="left_arm_joint_5" type="revolute">
    <parent link="left_arm_link4"/>
    <child link="left_arm_link5"/>
    <limit effort="300" lower="-3.0527" upper="3.0527" velocity="10"/>
    <axis xyz="0 0 1"/>
    <origin rpy="0 0 0" xyz="0 0 0.22044633"/>
  </joint>
  <transmission name="left_tran5">
    <type>transmission_interface/SimpleTransmission</type>
    <joint name="left_arm_joint_5">
      <hardwareInterface>EffortJointInterface</hardwareInterface>
    </joint>
    <actuator name="motor5">
      <hardwareInterface>EffortJointInterface</hardwareInterface>
      <mechanicalReduction>1</mechanicalReduction>
    </actuator>
  </transmission>
  <!--link 5-->
  <link name="left_arm_link5">
    <visual>
      <geometry>
        <mesh filename="./meshes/xmate3/meshes/visual/xmate3_link5.stl" scale="0.001 0.001 0.001"/>
      </geometry>
      <origin rpy="0 0 0" xyz="0 0 0.14512568"/>
      <material name="left_white"/>
    </visual>
    <inertial>
      <mass value="2.5992"/>
      <inertia ixx="0.022" ixy="0" ixz="0" iyy="0.018" iyz="0" izz="0.0076"/>
      <origin rpy="0 0 0" xyz="0 -0.025 -0.052"/>
    </inertial>
    <collision>
      <geometry>
        <mesh filename="./meshes/xmate3/meshes/collision/xmate3_link5.stl" scale="0.001 0.001 0.001"/>
      </geometry>
      <origin rpy="0 0 0" xyz="0 0 0.14512568"/>
    </collision>
  </link>
  <joint name="left_arm_joint_6" type="revolute">
    <parent link="left_arm_link5"/>
    <child link="left_arm_link6"/>
    <limit effort="300" lower="-2.0933" upper="2.0933" velocity="10"/>
    <axis xyz="0 1 0"/>
    <origin rpy="0.0 0.0 0" xyz="0 0 0.14512568"/>
  </joint>
  <transmission name="left_tran6">
    <type>transmission_interface/SimpleTransmission</type>
    <joint name="left_arm_joint_6">
      <hardwareInterface>EffortJointInterface</hardwareInterface>
    </joint>
    <actuator name="motor6">
      <hardwareInterface>EffortJointInterface</hardwareInterface>
      <mechanicalReduction>1</mechanicalReduction>
    </actuator>
  </transmission>
  <!--link 6-->
  <link name="left_arm_link6">
    <visual>
      <geometry>
        <mesh filename="./meshes/xmate3/meshes/visual/xmate3_link6.stl" scale="0.001 0.001 0.001"/>
      </geometry>
      <origin rpy="0 0 0" xyz="0.0 0.0 0.0"/>
      <material name="left_white"/>
    </visual>
    <inertial>
      <mass value="2.6002"/>
      <inertia ixx="0.016" ixy="-0.000000" ixz="-0.000000" iyy="0.0156" iyz="-0.000000" izz="0.0042"/>
      <origin rpy="0 0 0" xyz="0 0.02 0.073"/>
    </inertial>
    <collision>
      <geometry>
        <mesh filename="./meshes/xmate3/meshes/collision/xmate3_link6.stl" scale="0.001 0.001 0.001"/>
      </geometry>
      <origin rpy="0 0 0" xyz="0.0 0.0 0.0"/>
    </collision>
  </link>
  <joint name="left_arm_joint_7" type="revolute">
    <parent link="left_arm_link6"/>
    <child link="left_arm_link7"/>
    <limit effort="300" lower="-6.283" upper="6.283" velocity="10"/>
    <axis xyz="0 0 1"/>
    <origin rpy="0.0 0.0 0.0" xyz="0 0 0.25090877"/>
  </joint>
  <transmission name="left_tran7">
    <type>transmission_interface/SimpleTransmission</type>
    <joint name="left_arm_joint_7">
      <hardwareInterface>EffortJointInterface</hardwareInterface>
    </joint>
    <actuator name="motor7">
      <hardwareInterface>EffortJointInterface</hardwareInterface>
      <mechanicalReduction>1</mechanicalReduction>
    </actuator>
  </transmission>
  <!--link 7-->
  <link name="left_arm_link7">
    <visual>
      <geometry>
        <mesh filename="./meshes/xmate3/meshes/visual/xmate3_link7.stl" scale="0.001 0.001 0.001"/>
      </geometry>
      <origin rpy="0 0 0" xyz="0 0 0"/>
      <material name="left_white"/>
    </visual>
    <inertial>
      <mass value="1.50517"/>
      <inertia ixx="0.0037" ixy="0" ixz="0" iyy="0.0021" iyz="0" izz="0.0030"/>
      <origin rpy="0 0 0" xyz="0 0.023 -0.044"/>
    </inertial>
    <collision>
      <geometry>
        <mesh filename="./meshes/xmate3/meshes/collision/xmate3_link7.stl" scale="0.001 0.001 0.001"/>
      </geometry>
      <origin rpy="0 0 0" xyz="0 0 0"/>
    </collision>
  </link>
  <joint name="tobor_grasptarget_hand" type="fixed">
    <parent link="left_arm_link7"/>
    <child link="dhag95_grasp_target"/>
    <origin rpy="0 0 0" xyz="0 0 0.18"/>
  </joint>
  <link name="dhag95_grasp_target">
    <visual>  
      <geometry>  
        <sphere radius="0.01"/>  
      </geometry>  
      <origin rpy="0 0 0" xyz="0 0 0"/>  
    </visual>  
    <inertial>
      <origin rpy="0 0 0" xyz="0 0 0"/>
      <mass value="0.0"/>
      <inertia ixx="0.1" ixy="0" ixz="0" iyy="0.1" iyz="0" izz="0.1"/>
    </inertial>
   </link>
</robot>
