<?xml version="1.0" ?>
<!-- =================================================================================== -->
<!-- |    This document was autogenerated by xacro from r300_robot.xacro               | -->
<!-- |    EDITING THIS FILE BY HAND IS NOT RECOMMENDED                                 | -->
<!-- =================================================================================== -->
<robot name="r300">
    <link name="electric_cylinder_base_link">
        <inertial>
            <origin rpy="0 0 0" xyz="-0.19365 0.43875 0.51281" />
            <mass value="0.68116" />
            <inertia ixx="0.0020629" ixy="-0.00044209" ixz="-3.1301E-12" iyy="0.00093278" iyz="-2.18E-12" izz="0.0025262" />
        </inertial>
        <visual>
            <origin rpy="0 0 0" xyz="0 0 0" />
            <geometry>
                <mesh filename="meshes/lifting/meshes/dae/electric_cylinder_base_link.dae" />
            </geometry>
            <material name="">
                <color rgba="0.69804 0.69804 0.69804 1" />
            </material>
        </visual>
        <collision>
            <origin rpy="0 0 0" xyz="0 0 0" />
            <geometry>
                <mesh filename="meshes/lifting/meshes/stl/electric_cylinder_base_link.STL" />
            </geometry>
        </collision>
    </link>
    <link name="cylinder_link">
        <inertial>
            <origin rpy="0 0 0" xyz="-2.3637E-07 0.20854 0.0011345" />
            <mass value="0.47234" />
            <inertia ixx="0.0068471" ixy="2.0037E-08" ixz="1.0212E-09" iyy="0.00028887" iyz="1.0853E-05" izz="0.0068369" />
        </inertial>
        <visual>
            <origin rpy="0 0 0" xyz="0 0 0" />
            <geometry>
                <mesh filename="meshes/lifting/meshes/dae/cylinder_link.dae" />
            </geometry>
            <material name="">
                <color rgba="0.69804 0.69804 0.69804 1" />
            </material>
        </visual>
        <collision>
            <origin rpy="1.5707963 0 0" xyz="0 0 -0.060" />
            <geometry>
                <mesh filename="meshes/lifting/meshes/stl/cylinder_link.STL" />
            </geometry>
        </collision>
    </link>
    <joint name="joint_cylinder" type="fixed">
        <origin rpy="0 0 0" xyz="0.031152 0 0.06334" />
        <parent link="electric_cylinder_base_link" />
        <child link="cylinder_link" />
        <axis xyz="0 0 0" />
    </joint>
    <link name="lifting_rod_link">
        <inertial>
            <origin rpy="0 0 0" xyz="-2.7756E-17 0.17716 -1.1102E-16" />
            <mass value="0.17381" />
            <inertia ixx="0.0018298" ixy="1.468E-19" ixz="1.2399E-22" iyy="1.3427E-05" iyz="2.1083E-20" izz="0.0018298" />
        </inertial>
        <visual>
            <origin rpy="0 0 0" xyz="0 0 0" />
            <geometry>
                 <mesh filename="meshes/lifting/meshes/dae/lifting_rod_link.dae" />
            </geometry>
            <material name="">
                <color rgba="0.75294 0.75294 0.75294 1" />
            </material>
        </visual>
        <collision>
            <origin rpy="1.5707963 0 0" xyz="0 0 -0.060" />
            <geometry>
                <mesh filename="meshes/lifting/meshes/stl/lifting_rod_link.STL" />
            </geometry>
        </collision>
    </link>
    <joint name="joint_lifting_rod" type="prismatic">
        <origin rpy="0 0 0" xyz="0 0 0.03" />
        <axis xyz="0 0 1" />
        <parent link="cylinder_link" />
        <child link="lifting_rod_link" />
        <limit effort="30" lower="0" upper="0.3" velocity="1.0" />
    </joint>
    <joint name="joint_electric_cylinder_base" type="fixed">
        <origin rpy="0 0 0.39489" xyz="-0.028716 -0.010481 0.038" />
        <parent link="driven_gear_link" />
        <child link="electric_cylinder_base_link" />
        <axis xyz="0 0 0" />
    </joint>
    <link name="turn_to_link">
        <inertial>
            <origin rpy="0 0 0" xyz="-0.063764082051451 -0.223984714216175 -0.0252812454553025" />
            <mass value="7.74386372914031" />
            <inertia ixx="0.0769847292516015" ixy="-0.000273654810293264" ixz="-0.0141104719774003" iyy="0.119354131568816" iyz="0.000596796086896848" izz="0.0718902740521689" />
        </inertial>
        <visual>
            <origin rpy="0 0 0" xyz="0 0 0" />
            <geometry>
                <mesh filename="meshes/steering_module/meshes/dae/turn_to_link.dae" />
            </geometry>
            <material name="">
                <color rgba="0.890196078431372 0.890196078431372 0.913725490196078 1" />
            </material>
        </visual>
        <collision>
            <origin rpy="0 0 0" xyz="0 0 0" />
            <geometry>
                <mesh filename="meshes/steering_module/meshes/stl/turn_to_link.stl" />
            </geometry>
        </collision>
    </link>
    <link name="driving_gear_link">
        <inertial>
            <origin rpy="0 0 0" xyz="0.010011 -0.00018607 -1.0304E-09" />
            <mass value="0.018843" />
            <inertia ixx="4.7506E-06" ixy="-3.8571E-11" ixz="-4.2541E-15" iyy="3.0138E-06" iyz="3.8641E-13" izz="2.9764E-06" />
        </inertial>
        <visual>
            <origin rpy="0 0 0" xyz="0 0 0" />
            <geometry>
                <mesh filename="meshes/steering_module/meshes/dae/driving_gear_link.dae" />
            </geometry>
            <material name="">
                <color rgba="0.79216 0.81961 0.93333  1" />
            </material>
        </visual>
        <collision>
            <origin rpy="0 0 0" xyz="0 0 0" />
            <geometry>
                <mesh filename="meshes/steering_module/meshes/stl/driving_gear_link.stl" />
            </geometry>
        </collision>
    </link>
    <joint name="joint_driving_gear" type="continuous">
        <origin rpy="1.5707963 0 -1.5707963" xyz="-0.15141 -0.28522 -0.022722" />
        <parent link="turn_to_link" />
        <child link="driving_gear_link" />
        <axis xyz="1 0 0 " />
    </joint>
    <link name="driven_gear_link">
        <inertial>
            <origin rpy="0 0 0" xyz="3.89265716754308E-05 1.62060078654769E-05 0.0162446027714712" />
            <mass value="1.84024058367429" />
            <inertia ixx="0.00398005621390154" ixy="1.20915509078338E-06" ixz="-6.97309341864162E-07" iyy="0.00397765652813965" iyz="-2.87952744651294E-07" izz="0.00766666066271265" />
        </inertial>
        <visual>
            <origin rpy="0 0 0" xyz="0 0 0" />
            <geometry>
                <mesh filename="meshes/steering_module/meshes/dae/driven_gear_link.dae" />
            </geometry>
            <material name="">
                <color rgba="0.776470588235294 0.756862745098039 0.737254901960784 1" />
            </material>
        </visual>
        <collision>
            <origin rpy="0 0 0" xyz="0 0 0" />
            <geometry>
                <mesh filename="meshes/steering_module/meshes/stl/driven_gear_link.stl" />
            </geometry>
        </collision>
    </link>
    <joint name="joint_driven_gear" type="revolute">
        <origin rpy="-1.5707963 -0.3927 -3.1415926" xyz="-0.082469 -0.28422 -0.080572" />
        <parent link="turn_to_link" />
        <child link="driven_gear_link" />
        <axis xyz="0 0 1" />
        <limit effort="30" lower="-1.5707963" upper="1.5707963" velocity="1.0" />
    </joint>
    <joint name="joint_turn_to" type="fixed">
        <origin rpy="3.1415926 1.5707963  0" xyz="0.13943 -0.14822 -0.082469" />
        <parent link="support_plate_link" />
        <child link="turn_to_link" />
        <axis xyz="0 0 0" />
    </joint>
    <!-- Constants for robot dimensions -->
    <material name="left_black">
        <color rgba="0.0 0.0 0.0 1.0" />
    </material>
    <material name="left_blue">
        <color rgba="0.0 0.0 0.8 1.0" />
    </material>
    <material name="left_green">
        <color rgba="0.0 0.8 0.0 1.0" />
    </material>
    <material name="left_grey">
        <color rgba="0.2 0.2 0.2 1.0" />
    </material>
    <material name="left_orange">
        <color rgba="1.0 0.4235294117647059 0.0392156862745098 1.0" />
    </material>
    <material name="left_brown">
        <color rgba="0.8705882352941177 0.8117647058823529 0.7647058823529411 1.0" />
    </material>
    <material name="left_red">
        <color rgba="0.8 0.0 0.0 1.0" />
    </material>
    <material name="left_white">
        <color rgba="1.0 1.0 1.0 1.0" />
    </material>
    <material name="left_Beige">
        <color rgba="1.0 0.784 0.5765 1.0" />
    </material>
    <!-- Used for fixing robot to Gazebo 'base_link' -->
    <!--link name="world"/>
    <joint name="fixed" type="fixed">
    <parent link="world"/>
    <child link="${nameofManipulator}_base"/>
  </joint-->
    <!--base-->
    <link name="left_arm_base">
        <visual>
            <geometry>
                <mesh filename="meshes/xmate3/meshes/visual/xmate3_base.stl" scale="0.001 0.001 0.001" />
            </geometry>
            <origin rpy="0 0 0" xyz="0.0 0.0 0.0" />
            <material name="left_white" />
        </visual>
        <inertial>
            <mass value="5.48267" />
            <inertia ixx="0.056" ixy="0" ixz="0" iyy="0.066" iyz="0" izz="0.035" />
            <origin rpy="0 0 0" xyz="-0.0183 0 0.067" />
        </inertial>
        <collision>
            <geometry>
                <mesh filename="meshes/xmate3/meshes/collision/xmate3_base.stl" scale="0.001 0.001 0.001" />
            </geometry>
            <origin rpy="0 0 0" xyz="0.0 0.0 0.0" />
        </collision>
    </link>
    <joint name="left_arm_joint_1" type="revolute">
        <parent link="left_arm_base" />
        <child link="left_arm_link1" />
        <limit effort="300" lower="-3.0527" upper="3.0527" velocity="10" />
        <axis xyz="0 0 1" />
        <origin rpy="0 0 0" xyz="0 0 0" />
    </joint>
    <transmission name="left_tran1">
        <type>transmission_interface/SimpleTransmission</type>
        <joint name="left_arm_joint_1">
            <hardwareInterface>EffortJointInterface</hardwareInterface>
        </joint>
        <actuator name="motor1">
            <hardwareInterface>EffortJointInterface</hardwareInterface>
            <mechanicalReduction>1</mechanicalReduction>
        </actuator>
    </transmission>
    <!--link 1-->
    <link name="left_arm_link1">
        <visual>
            <geometry>
                <mesh filename="meshes/xmate3/meshes/visual/xmate3_link1.stl" scale="0.001 0.001 0.001" />
            </geometry>
            <origin rpy="0 0 0" xyz="0 0 0" />
            <material name="left_white" />
        </visual>
        <inertial>
            <mass value="3.37289" />
            <inertia ixx="0.314" ixy="0" ixz="0" iyy="0.310" iyz="0" izz="0.01" />
            <origin rpy="0 0 0" xyz="0 -0.023 0.295" />
        </inertial>
        <collision>
            <geometry>
                <mesh filename="meshes/xmate3/meshes/collision/xmate3_link1.stl" scale="0.001 0.001 0.001" />
            </geometry>
            <origin rpy="0 0 0" xyz="0 0 0" />
        </collision>
    </link>
    <joint name="left_arm_joint_2" type="revolute">
        <parent link="left_arm_link1" />
        <child link="left_arm_link2" />
        <limit effort="300" lower="-2.0933" upper="2.0933" velocity="10" />
        <axis xyz="0 1 0" />
        <origin rpy="0 0 0" xyz="0 0 0.34260487" />
    </joint>
    <transmission name="left_tran2">
        <type>transmission_interface/SimpleTransmission</type>
        <joint name="left_arm_joint_2">
            <hardwareInterface>EffortJointInterface</hardwareInterface>
        </joint>
        <actuator name="motor2">
            <hardwareInterface>EffortJointInterface</hardwareInterface>
            <mechanicalReduction>1</mechanicalReduction>
        </actuator>
    </transmission>
    <!--link 2-->
    <link name="left_arm_link2">
        <visual>
            <geometry>
                <mesh filename="meshes/xmate3/meshes/visual/xmate3_link2.stl" scale="0.001 0.001 0.001" />
            </geometry>
            <origin rpy="0 0 0" xyz="0 0 0.0" />
            <material name="left_white" />
        </visual>
        <inertial>
            <mass value="3.74765" />
            <inertia ixx="0.074" ixy="0" ixz="0" iyy="0.067" iyz="0" izz="0.014" />
            <origin rpy="0 0 0" xyz="0 0.032 0.095" />
        </inertial>
        <collision>
            <geometry>
                <mesh filename="meshes/xmate3/meshes/collision/xmate3_link2.stl" scale="0.001 0.001 0.001" />
            </geometry>
            <origin rpy="0 0 0" xyz="0 0 0.0" />
        </collision>
    </link>
    <joint name="left_arm_joint_3" type="revolute">
        <parent link="left_arm_link2" />
        <child link="left_arm_link3" />
        <limit effort="300" lower="-3.0527" upper="3.0527" velocity="10" />
        <axis xyz="0 0 1" />
        <origin rpy="0 0 0" xyz="0 0 0.23743878" />
    </joint>
    <transmission name="left_tran3">
        <type>transmission_interface/SimpleTransmission</type>
        <joint name="left_arm_joint_3">
            <hardwareInterface>EffortJointInterface</hardwareInterface>
        </joint>
        <actuator name="motor3">
            <hardwareInterface>EffortJointInterface</hardwareInterface>
            <mechanicalReduction>1</mechanicalReduction>
        </actuator>
    </transmission>
    <!--${nameofManipulator}_link 3-->
    <link name="left_arm_link3">
        <visual>
            <geometry>
                <mesh filename="meshes/xmate3/meshes/visual/xmate3_link3.stl" scale="0.001 0.001 0.001" />
            </geometry>
            <origin rpy="0 0 0" xyz="0 0 0.15549959" />
            <material name="left_white" />
        </visual>
        <inertial>
            <mass value="3.38216" />
            <inertia ixx="0.028" ixy="0" ixz="0" iyy="0.025" iyz="0" izz="0.01" />
            <origin rpy="0 0 0" xyz="0 -0.023 -0.048" />
        </inertial>
        <collision>
            <geometry>
                <mesh filename="meshes/xmate3/meshes/collision/xmate3_link3.stl" scale="0.001 0.001 0.001" />
            </geometry>
            <origin rpy="0 0 0" xyz="0 0 0.15549959" />
        </collision>
    </link>
    <joint name="left_arm_joint_4" type="revolute">
        <parent link="left_arm_link3" />
        <child link="left_arm_link4" />
        <limit effort="300" lower="-2.0933" upper="2.0933" velocity="10" />
        <!--     lower="-2.79" upper="2.79" -->
        <axis xyz="0 1 0" />
        <!--     <origin rpy="0 0 0" xyz="0.585 0.0 0.035"/> -->
        <origin rpy="0 0 0" xyz="0 0 0.15549959" />
    </joint>
    <transmission name="left_tran4">
        <type>transmission_interface/SimpleTransmission</type>
        <joint name="left_arm_joint_4">
            <hardwareInterface>EffortJointInterface</hardwareInterface>
        </joint>
        <actuator name="motor4">
            <hardwareInterface>EffortJointInterface</hardwareInterface>
            <mechanicalReduction>1</mechanicalReduction>
        </actuator>
    </transmission>
    <!--link 4-->
    <link name="left_arm_link4">
        <visual>
            <geometry>
                <mesh filename="meshes/xmate3/meshes/visual/xmate3_link4.stl" scale=".001 0.001 0.001" />
            </geometry>
            <origin rpy="0 0 0" xyz="0.0 0.0 0.0" />
            <material name="left_white" />
        </visual>
        <inertial>
            <mass value="3.21031" />
            <inertia ixx="0.027" ixy="0" ixz="0" iyy="0.024" iyz="0" izz="0.007" />
            <origin rpy="0 0 0" xyz="0 0.037 0.075" />
        </inertial>
        <collision>
            <geometry>
                <mesh filename="meshes/xmate3/meshes/collision/xmate3_link4.stl" scale="0.001 0.001 0.001" />
            </geometry>
            <origin rpy="0 0 0" xyz="0.0 0.0 0.0" />
        </collision>
    </link>
    <joint name="left_arm_joint_5" type="revolute">
        <parent link="left_arm_link4" />
        <child link="left_arm_link5" />
        <limit effort="300" lower="-3.0527" upper="3.0527" velocity="10" />
        <axis xyz="0 0 1" />
        <origin rpy="0 0 0" xyz="0 0 0.22044633" />
    </joint>
    <transmission name="left_tran5">
        <type>transmission_interface/SimpleTransmission</type>
        <joint name="left_arm_joint_5">
            <hardwareInterface>EffortJointInterface</hardwareInterface>
        </joint>
        <actuator name="motor5">
            <hardwareInterface>EffortJointInterface</hardwareInterface>
            <mechanicalReduction>1</mechanicalReduction>
        </actuator>
    </transmission>
    <!--link 5-->
    <link name="left_arm_link5">
        <visual>
            <geometry>
                <mesh filename="meshes/xmate3/meshes/visual/xmate3_link5.stl" scale="0.001 0.001 0.001" />
            </geometry>
            <origin rpy="0 0 0" xyz="0 0 0.14512568" />
            <material name="left_white" />
        </visual>
        <inertial>
            <mass value="2.5992" />
            <inertia ixx="0.022" ixy="0" ixz="0" iyy="0.018" iyz="0" izz="0.0076" />
            <origin rpy="0 0 0" xyz="0 -0.025 -0.052" />
        </inertial>
        <collision>
            <geometry>
                <mesh filename="meshes/xmate3/meshes/collision/xmate3_link5.stl" scale="0.001 0.001 0.001" />
            </geometry>
            <origin rpy="0 0 0" xyz="0 0 0.14512568" />
        </collision>
    </link>
    <joint name="left_arm_joint_6" type="revolute">
        <parent link="left_arm_link5" />
        <child link="left_arm_link6" />
        <limit effort="300" lower="-2.0933" upper="2.0933" velocity="10" />
        <axis xyz="0 1 0" />
        <origin rpy="0.0 0.0 0" xyz="0 0 0.14512568" />
    </joint>
    <transmission name="left_tran6">
        <type>transmission_interface/SimpleTransmission</type>
        <joint name="left_arm_joint_6">
            <hardwareInterface>EffortJointInterface</hardwareInterface>
        </joint>
        <actuator name="motor6">
            <hardwareInterface>EffortJointInterface</hardwareInterface>
            <mechanicalReduction>1</mechanicalReduction>
        </actuator>
    </transmission>
    <!--link 6-->
    <link name="left_arm_link6">
        <visual>
            <geometry>
                <mesh filename="meshes/xmate3/meshes/visual/xmate3_link6.stl" scale="0.001 0.001 0.001" />
            </geometry>
            <origin rpy="0 0 0" xyz="0.0 0.0 0.0" />
            <material name="left_white" />
        </visual>
        <inertial>
            <mass value="2.6002" />
            <inertia ixx="0.016" ixy="-0.000000" ixz="-0.000000" iyy="0.0156" iyz="-0.000000" izz="0.0042" />
            <origin rpy="0 0 0" xyz="0 0.02 0.073" />
        </inertial>
        <collision>
            <geometry>
                <mesh filename="meshes/xmate3/meshes/collision/xmate3_link6.stl" scale="0.001 0.001 0.001" />
            </geometry>
            <origin rpy="0 0 0" xyz="0.0 0.0 0.0" />
        </collision>
    </link>
    <joint name="left_arm_joint_7" type="revolute">
        <parent link="left_arm_link6" />
        <child link="left_arm_link7" />
        <limit effort="300" lower="-6.283" upper="6.283" velocity="10" />
        <axis xyz="0 0 1" />
        <origin rpy="0.0 0.0 0.0" xyz="0 0 0.25090877" />
    </joint>
    <transmission name="left_tran7">
        <type>transmission_interface/SimpleTransmission</type>
        <joint name="left_arm_joint_7">
            <hardwareInterface>EffortJointInterface</hardwareInterface>
        </joint>
        <actuator name="motor7">
            <hardwareInterface>EffortJointInterface</hardwareInterface>
            <mechanicalReduction>1</mechanicalReduction>
        </actuator>
    </transmission>
    <!--link 7-->
    <link name="left_arm_link7">
        <visual>
            <geometry>
                <mesh filename="meshes/xmate3/meshes/visual/xmate3_link7.stl" scale="0.001 0.001 0.001" />
            </geometry>
            <origin rpy="0 0 0" xyz="0 0 0" />
            <material name="left_white" />
        </visual>
        <inertial>
            <mass value="1.50517" />
            <inertia ixx="0.0037" ixy="0" ixz="0" iyy="0.0021" iyz="0" izz="0.0030" />
            <origin rpy="0 0 0" xyz="0 0.023 -0.044" />
        </inertial>
        <collision>
            <geometry>
                <mesh filename="meshes/xmate3/meshes/collision/xmate3_link7.stl" scale="0.001 0.001 0.001" />
            </geometry>
            <origin rpy="0 0 0" xyz="0 0 0" />
        </collision>
    </link>
    <joint name="joint_left_arm" type="fixed">
        <origin rpy="-1.5707963 0.019125 -1.5707963" xyz="0.067988 -0.123 -0.00056548" />
        <parent link="fixed_frame_link" />
        <child link="left_arm_base" />
        <axis xyz="0 0 0" />
    </joint>
    <!-- Constants for robot dimensions -->
    <material name="right_black">
        <color rgba="0.0 0.0 0.0 1.0" />
    </material>
    <material name="right_blue">
        <color rgba="0.0 0.0 0.8 1.0" />
    </material>
    <material name="right_green">
        <color rgba="0.0 0.8 0.0 1.0" />
    </material>
    <material name="right_grey">
        <color rgba="0.2 0.2 0.2 1.0" />
    </material>
    <material name="right_orange">
        <color rgba="1.0 0.4235294117647059 0.0392156862745098 1.0" />
    </material>
    <material name="right_brown">
        <color rgba="0.8705882352941177 0.8117647058823529 0.7647058823529411 1.0" />
    </material>
    <material name="right_red">
        <color rgba="0.8 0.0 0.0 1.0" />
    </material>
    <material name="right_white">
        <color rgba="1.0 1.0 1.0 1.0" />
    </material>
    <material name="right_Beige">
        <color rgba="1.0 0.784 0.5765 1.0" />
    </material>
    <!-- Used for fixing robot to Gazebo 'base_link' -->
    <!--link name="world"/>
    <joint name="fixed" type="fixed">
    <parent link="world"/>
    <child link="${nameofManipulator}_base"/>
  </joint-->
    <!--base-->
    <link name="right_arm_base">
        <visual>
            <geometry>
                <mesh filename="meshes/xmate3/meshes/visual/xmate3_base.stl" scale="0.001 0.001 0.001" />
            </geometry>
            <origin rpy="0 0 0" xyz="0.0 0.0 0.0" />
            <material name="right_white" />
        </visual>
        <inertial>
            <mass value="5.48267" />
            <inertia ixx="0.056" ixy="0" ixz="0" iyy="0.066" iyz="0" izz="0.035" />
            <origin rpy="0 0 0" xyz="-0.0183 0 0.067" />
        </inertial>
        <collision>
            <geometry>
                <mesh filename="meshes/xmate3/meshes/collision/xmate3_base.stl" scale="0.001 0.001 0.001" />
            </geometry>
            <origin rpy="0 0 0" xyz="0.0 0.0 0.0" />
        </collision>
    </link>
    <joint name="right_arm_joint_1" type="revolute">
        <parent link="right_arm_base" />
        <child link="right_arm_link1" />
        <limit effort="300" lower="-3.0527" upper="3.0527" velocity="10" />
        <axis xyz="0 0 1" />
        <origin rpy="0 0 0" xyz="0 0 0" />
    </joint>
    <transmission name="right_tran1">
        <type>transmission_interface/SimpleTransmission</type>
        <joint name="right_arm_joint_1">
            <hardwareInterface>EffortJointInterface</hardwareInterface>
        </joint>
        <actuator name="motor1">
            <hardwareInterface>EffortJointInterface</hardwareInterface>
            <mechanicalReduction>1</mechanicalReduction>
        </actuator>
    </transmission>
    <!--link 1-->
    <link name="right_arm_link1">
        <visual>
            <geometry>
                <mesh filename="meshes/xmate3/meshes/visual/xmate3_link1.stl" scale="0.001 0.001 0.001" />
            </geometry>
            <origin rpy="0 0 0" xyz="0 0 0" />
            <material name="right_white" />
        </visual>
        <inertial>
            <mass value="3.37289" />
            <inertia ixx="0.314" ixy="0" ixz="0" iyy="0.310" iyz="0" izz="0.01" />
            <origin rpy="0 0 0" xyz="0 -0.023 0.295" />
        </inertial>
        <collision>
            <geometry>
                <mesh filename="meshes/xmate3/meshes/collision/xmate3_link1.stl" scale="0.001 0.001 0.001" />
            </geometry>
            <origin rpy="0 0 0" xyz="0 0 0" />
        </collision>
    </link>
    <joint name="right_arm_joint_2" type="revolute">
        <parent link="right_arm_link1" />
        <child link="right_arm_link2" />
        <limit effort="300" lower="-2.0933" upper="2.0933" velocity="10" />
        <axis xyz="0 1 0" />
        <origin rpy="0 0 0" xyz="0 0 0.34260487" />
    </joint>
    <transmission name="right_tran2">
        <type>transmission_interface/SimpleTransmission</type>
        <joint name="right_arm_joint_2">
            <hardwareInterface>EffortJointInterface</hardwareInterface>
        </joint>
        <actuator name="motor2">
            <hardwareInterface>EffortJointInterface</hardwareInterface>
            <mechanicalReduction>1</mechanicalReduction>
        </actuator>
    </transmission>
    <!--link 2-->
    <link name="right_arm_link2">
        <visual>
            <geometry>
                <mesh filename="meshes/xmate3/meshes/visual/xmate3_link2.stl" scale="0.001 0.001 0.001" />
            </geometry>
            <origin rpy="0 0 0" xyz="0 0 0.0" />
            <material name="right_white" />
        </visual>
        <inertial>
            <mass value="3.74765" />
            <inertia ixx="0.074" ixy="0" ixz="0" iyy="0.067" iyz="0" izz="0.014" />
            <origin rpy="0 0 0" xyz="0 0.032 0.095" />
        </inertial>
        <collision>
            <geometry>
                <mesh filename="meshes/xmate3/meshes/collision/xmate3_link2.stl" scale="0.001 0.001 0.001" />
            </geometry>
            <origin rpy="0 0 0" xyz="0 0 0.0" />
        </collision>
    </link>
    <joint name="right_arm_joint_3" type="revolute">
        <parent link="right_arm_link2" />
        <child link="right_arm_link3" />
        <limit effort="300" lower="-3.0527" upper="3.0527" velocity="10" />
        <axis xyz="0 0 1" />
        <origin rpy="0 0 0" xyz="0 0 0.23743878" />
    </joint>
    <transmission name="right_tran3">
        <type>transmission_interface/SimpleTransmission</type>
        <joint name="right_arm_joint_3">
            <hardwareInterface>EffortJointInterface</hardwareInterface>
        </joint>
        <actuator name="motor3">
            <hardwareInterface>EffortJointInterface</hardwareInterface>
            <mechanicalReduction>1</mechanicalReduction>
        </actuator>
    </transmission>
    <!--${nameofManipulator}_link 3-->
    <link name="right_arm_link3">
        <visual>
            <geometry>
                <mesh filename="meshes/xmate3/meshes/visual/xmate3_link3.stl" scale="0.001 0.001 0.001" />
            </geometry>
            <origin rpy="0 0 0" xyz="0 0 0.15549959" />
            <material name="right_white" />
        </visual>
        <inertial>
            <mass value="3.38216" />
            <inertia ixx="0.028" ixy="0" ixz="0" iyy="0.025" iyz="0" izz="0.01" />
            <origin rpy="0 0 0" xyz="0 -0.023 -0.048" />
        </inertial>
        <collision>
            <geometry>
                <mesh filename="meshes/xmate3/meshes/collision/xmate3_link3.stl" scale="0.001 0.001 0.001" />
            </geometry>
            <origin rpy="0 0 0" xyz="0 0 0.15549959" />
        </collision>
    </link>
    <joint name="right_arm_joint_4" type="revolute">
        <parent link="right_arm_link3" />
        <child link="right_arm_link4" />
        <limit effort="300" lower="-2.0933" upper="2.0933" velocity="10" />
        <!--     lower="-2.79" upper="2.79" -->
        <axis xyz="0 1 0" />
        <!--     <origin rpy="0 0 0" xyz="0.585 0.0 0.035"/> -->
        <origin rpy="0 0 0" xyz="0 0 0.15549959" />
    </joint>
    <transmission name="right_tran4">
        <type>transmission_interface/SimpleTransmission</type>
        <joint name="right_arm_joint_4">
            <hardwareInterface>EffortJointInterface</hardwareInterface>
        </joint>
        <actuator name="motor4">
            <hardwareInterface>EffortJointInterface</hardwareInterface>
            <mechanicalReduction>1</mechanicalReduction>
        </actuator>
    </transmission>
    <!--link 4-->
    <link name="right_arm_link4">
        <visual>
            <geometry>
                <mesh filename="meshes/xmate3/meshes/visual/xmate3_link4.stl" scale=".001 0.001 0.001" />
            </geometry>
            <origin rpy="0 0 0" xyz="0.0 0.0 0.0" />
            <material name="right_white" />
        </visual>
        <inertial>
            <mass value="3.21031" />
            <inertia ixx="0.027" ixy="0" ixz="0" iyy="0.024" iyz="0" izz="0.007" />
            <origin rpy="0 0 0" xyz="0 0.037 0.075" />
        </inertial>
        <collision>
            <geometry>
                <mesh filename="meshes/xmate3/meshes/collision/xmate3_link4.stl" scale="0.001 0.001 0.001" />
            </geometry>
            <origin rpy="0 0 0" xyz="0.0 0.0 0.0" />
        </collision>
    </link>
    <joint name="right_arm_joint_5" type="revolute">
        <parent link="right_arm_link4" />
        <child link="right_arm_link5" />
        <limit effort="300" lower="-3.0527" upper="3.0527" velocity="10" />
        <axis xyz="0 0 1" />
        <origin rpy="0 0 0" xyz="0 0 0.22044633" />
    </joint>
    <transmission name="right_tran5">
        <type>transmission_interface/SimpleTransmission</type>
        <joint name="right_arm_joint_5">
            <hardwareInterface>EffortJointInterface</hardwareInterface>
        </joint>
        <actuator name="motor5">
            <hardwareInterface>EffortJointInterface</hardwareInterface>
            <mechanicalReduction>1</mechanicalReduction>
        </actuator>
    </transmission>
    <!--link 5-->
    <link name="right_arm_link5">
        <visual>
            <geometry>
                <mesh filename="meshes/xmate3/meshes/visual/xmate3_link5.stl" scale="0.001 0.001 0.001" />
            </geometry>
            <origin rpy="0 0 0" xyz="0 0 0.14512568" />
            <material name="right_white" />
        </visual>
        <inertial>
            <mass value="2.5992" />
            <inertia ixx="0.022" ixy="0" ixz="0" iyy="0.018" iyz="0" izz="0.0076" />
            <origin rpy="0 0 0" xyz="0 -0.025 -0.052" />
        </inertial>
        <collision>
            <geometry>
                <mesh filename="meshes/xmate3/meshes/collision/xmate3_link5.stl" scale="0.001 0.001 0.001" />
            </geometry>
            <origin rpy="0 0 0" xyz="0 0 0.14512568" />
        </collision>
    </link>
    <joint name="right_arm_joint_6" type="revolute">
        <parent link="right_arm_link5" />
        <child link="right_arm_link6" />
        <limit effort="300" lower="-2.0933" upper="2.0933" velocity="10" />
        <axis xyz="0 1 0" />
        <origin rpy="0.0 0.0 0" xyz="0 0 0.14512568" />
    </joint>
    <transmission name="right_tran6">
        <type>transmission_interface/SimpleTransmission</type>
        <joint name="right_arm_joint_6">
            <hardwareInterface>EffortJointInterface</hardwareInterface>
        </joint>
        <actuator name="motor6">
            <hardwareInterface>EffortJointInterface</hardwareInterface>
            <mechanicalReduction>1</mechanicalReduction>
        </actuator>
    </transmission>
    <!--link 6-->
    <link name="right_arm_link6">
        <visual>
            <geometry>
                <mesh filename="meshes/xmate3/meshes/visual/xmate3_link6.stl" scale="0.001 0.001 0.001" />
            </geometry>
            <origin rpy="0 0 0" xyz="0.0 0.0 0.0" />
            <material name="right_white" />
        </visual>
        <inertial>
            <mass value="2.6002" />
            <inertia ixx="0.016" ixy="-0.000000" ixz="-0.000000" iyy="0.0156" iyz="-0.000000" izz="0.0042" />
            <origin rpy="0 0 0" xyz="0 0.02 0.073" />
        </inertial>
        <collision>
            <geometry>
                <mesh filename="meshes/xmate3/meshes/collision/xmate3_link6.stl" scale="0.001 0.001 0.001" />
            </geometry>
            <origin rpy="0 0 0" xyz="0.0 0.0 0.0" />
        </collision>
    </link>
    <joint name="right_arm_joint_7" type="revolute">
        <parent link="right_arm_link6" />
        <child link="right_arm_link7" />
        <limit effort="300" lower="-6.283" upper="6.283" velocity="10" />
        <axis xyz="0 0 1" />
        <origin rpy="0.0 0.0 0.0" xyz="0 0 0.25090877" />
    </joint>
    <transmission name="right_tran7">
        <type>transmission_interface/SimpleTransmission</type>
        <joint name="right_arm_joint_7">
            <hardwareInterface>EffortJointInterface</hardwareInterface>
        </joint>
        <actuator name="motor7">
            <hardwareInterface>EffortJointInterface</hardwareInterface>
            <mechanicalReduction>1</mechanicalReduction>
        </actuator>
    </transmission>
    <!--link 7-->
    <link name="right_arm_link7">
        <visual>
            <geometry>
                <mesh filename="meshes/xmate3/meshes/visual/xmate3_link7.stl" scale="0.001 0.001 0.001" />
            </geometry>
            <origin rpy="0 0 0" xyz="0 0 0" />
            <material name="right_white" />
        </visual>
        <inertial>
            <mass value="1.50517" />
            <inertia ixx="0.0037" ixy="0" ixz="0" iyy="0.0021" iyz="0" izz="0.0030" />
            <origin rpy="0 0 0" xyz="0 0.023 -0.044" />
        </inertial>
        <collision>
            <geometry>
                <mesh filename="meshes/xmate3/meshes/collision/xmate3_link7.stl" scale="0.001 0.001 0.001" />
            </geometry>
            <origin rpy="0 0 0" xyz="0 0 0" />
        </collision>
    </link>
    <joint name="joint_right_arm" type="fixed">
        <origin rpy="1.5707963 -0.019126 -1.5707963" xyz="-0.068 -0.123 -0.00021044" />
        <parent link="fixed_frame_link" />
        <child link="right_arm_base" />
        <axis xyz="0 0 0" />
    </joint>
    <link name="PTZ_base_link">
        <inertial>
            <origin rpy="0 0 0" xyz="-1.8317E-05 -0.0064414 -0.00088958" />
            <mass value="0.11363" />
            <inertia ixx="0.00010358" ixy="-3.8626E-08" ixz="9.6564E-09" iyy="5.6915E-05" iyz="4.8822E-08" izz="0.00010171" />
        </inertial>
        <visual>
            <origin rpy="0 0 0" xyz="0 0 0" />
            <geometry>
                <mesh filename="meshes/ptz/meshes/dae/PTZ_base_link.dae" />
            </geometry>
            <material name="">
                <color rgba="0.75294 0.75294 0.75294 1" />
            </material>
        </visual>
        <collision>
            <origin rpy="0 0 0" xyz="0 0 0" />
            <geometry>
                <mesh filename="meshes/ptz/meshes/stl/PTZ_base_link.stl" />
            </geometry>
        </collision>
    </link>
    <link name="fixed_PTZ_link">
        <inertial>
            <origin rpy="0 0 0" xyz="-4.886E-05 -0.028514 -0.013925" />
            <mass value="0.36918" />
            <inertia ixx="0.0010871" ixy="-2.8773E-07" ixz="2.8626E-07" iyy="0.0020864" iyz="-0.0002127" izz="0.0021051" />
        </inertial>
        <visual>
            <origin rpy="0 0 0" xyz="0 0 0" />
            <geometry>
                <mesh filename="meshes/ptz/meshes/dae/fixed_PTZ_link.dae" />
            </geometry>
            <material name="">
                <color rgba="0.79216 0.81961 0.93333 1" />
            </material>
        </visual>
        <collision>
            <origin rpy="0 0 0" xyz="0 0 0" />
            <geometry>
                <mesh filename="meshes/ptz/meshes/stl/fixed_PTZ_link.stl" />
            </geometry>
        </collision>
    </link>
    <joint name="joint_fixed_PTZ" type="fixed">
        <origin rpy="-1.5707963 0 -1.5707963" xyz="0.006142 0 -0.0194154" />
        <parent link="PTZ_head_link" />
        <child link="fixed_PTZ_link" />
        <axis xyz="0 0 0" />
    </joint>
    <link name="PTZ_head_link">
        <inertial>
            <origin rpy="0 0 0" xyz="-0.00041874 0.0031623 -0.00071235" />
            <mass value="0.053787" />
            <inertia ixx="1.9442E-05" ixy="2.0673E-07" ixz="-2.0477E-07" iyy="0.00012094" iyz="-2.4307E-07" izz="0.00012812" />
        </inertial>
        <visual>
            <origin rpy="0 0 0" xyz="0 0 0" />
            <geometry>
                <mesh filename="meshes/ptz/meshes/dae/PTZ_head_link.dae" />
            </geometry>
            <material name="">
                <color rgba="1 1 1 1" />
            </material>
        </visual>
        <collision>
            <origin rpy="0 0 0" xyz="0 0 0" />
            <geometry>
                <mesh filename="meshes/ptz/meshes/stl/PTZ_head_link.stl" />
            </geometry>
        </collision>
    </link>
    <joint name="joint_PTZ_head" type="revolute">
        <origin rpy="0 0 0" xyz="-0.0101743 0 0.05485" />
        <parent link="PTZ_base_link" />
        <child link="PTZ_head_link" />
        <axis xyz="0 0 1" />
        <limit effort="30" lower="-1.2566370400000002" upper="1.2566370400000002" velocity="1.0" />
    </joint>
    <link name="PTZ_axis_link">
        <inertial>
            <origin rpy="0 0 0" xyz="-0.00041874 0.0031623 -0.00071235" />
            <mass value="0.053787" />
            <inertia ixx="1.9442E-05" ixy="2.0673E-07" ixz="-2.0477E-07" iyy="0.00012094" iyz="-2.4307E-07" izz="0.00012812" />
        </inertial>
        <visual>
            <origin rpy="0 0 0" xyz="0 0 0" />
            <geometry>
                <mesh filename="meshes/ptz/meshes/dae/PTZ_axis_link.dae" />
            </geometry>
            <material name="">
                <color rgba="1 1 1 1" />
            </material>
        </visual>
        <collision>
            <origin rpy="0 0 0" xyz="0 0 0" />
            <geometry>
                <mesh filename="meshes/ptz/meshes/stl/PTZ_axis_link.stl" />
            </geometry>
        </collision>
    </link>
    <joint name="joint_PTZ_axis" type="revolute">
        <origin rpy="0 0 0" xyz="0.01545 0 0" />
        <parent link="PTZ_head_link" />
        <child link="PTZ_axis_link" />
        <axis xyz="0 1 0" />
        <limit effort="30" lower="-0.78539815" upper="0.78539815" velocity="1.0" />
    </joint>
    <link name="PTZ_link">
        <inertial>
            <origin rpy="0 0 0" xyz="-0.00041874 0.0031623 -0.00071235" />
            <mass value="0.053787" />
            <inertia ixx="1.9442E-05" ixy="2.0673E-07" ixz="-2.0477E-07" iyy="0.00012094" iyz="-2.4307E-07" izz="0.00012812" />
        </inertial>
        <visual>
            <origin rpy="0 0 0" xyz="0 0 0" />
            <geometry>
                <mesh filename="meshes/ptz/meshes/dae/PTZ_link.dae" />
            </geometry>
            <material name="">
                <color rgba="1 1 1 1" />
            </material>
        </visual>
        <collision>
            <origin rpy="0 0 0" xyz="0 0 0" />
            <geometry>
                <mesh filename="meshes/ptz/meshes/stl/PTZ_link.stl" />
            </geometry>
        </collision>
    </link>
    <joint name="joint_PTZ" type="fixed">
        <origin rpy="1.5707963 3.1415926 1.5707963" xyz="-0.00205 0 0" />
        <parent link="PTZ_axis_link" />
        <child link="PTZ_link" />
        <axis xyz="0 0 0" />
    </joint>
    <joint name="joint_PTZ_base" type="fixed">
        <origin rpy="1.5707963 1.5707963 0" xyz="0 -0.289045 -0.0010432" />
        <parent link="fixed_frame_link" />
        <child link="PTZ_base_link" />
        <axis xyz="0 0 0" />
    </joint>
    <material name="aluminum">
        <color rgba="0.5 0.5 0.5 1" />
    </material>
    <material name="plastic">
        <color rgba="0.1 0.1 0.1 1" />
    </material>
    <!-- camera body, with origin at bottom screw mount -->
    <joint name="PTZ_camera_joint" type="fixed">
        <origin rpy="0 -1.5707963 1.5707963" xyz="0 -0.044316 0" />
        <parent link="PTZ_link" />
        <child link="PTZ_camera_bottom_screw_frame" />
    </joint>
    <link name="PTZ_camera_bottom_screw_frame" />
    <joint name="PTZ_camera_link_joint" type="fixed">
        <origin rpy="0 0 0" xyz="0.010600000000000002 0.0175 0.0125" />
        <parent link="PTZ_camera_bottom_screw_frame" />
        <child link="PTZ_camera_link" />
    </joint>
    <link name="PTZ_camera_link">
        <visual>
            <!-- the mesh origin is at front plate in between the two infrared camera axes -->
            <origin rpy="1.5707963267948966 0 1.5707963267948966" xyz="0.0043 -0.0175 0" />
            <geometry>
                <!-- <box size="${d435_cam_width} ${d435_cam_height} ${d435_cam_depth}"/> -->
                <mesh filename="meshes/realsense2/meshes/d435.dae" />
            </geometry>
        </visual>
        <collision>
            <origin rpy="0 0 0" xyz="0 -0.0175 0" />
            <geometry>
                <box size="0.02505 0.09 0.025" />
            </geometry>
        </collision>
        <inertial>
            <!-- The following are not reliable values, and should not be used for modeling -->
            <mass value="0.072" />
            <origin xyz="0 0 0" rpy="0 0 0" />
            <inertia ixx="0.003881243" ixy="0.0" ixz="0.0" iyy="0.000498940" iyz="0.0" izz="0.003879257" />
        </inertial>
    </link>
    <material name="OffWhite">
        <color rgba="0.8 0.8 0.8 1.0" />
    </material>
    <link name="base_link">
        <!--<inertial>
            <mass value="0.0001" />
            <origin xyz=" 0  0  0" rpy="0 0 0" />
            <inertia ixx="0.0001" ixy="0.0" ixz="0.0" iyy="0.0001" iyz="0.0" izz="0.0001" />
        </inertial>-->
        <visual>
            <origin rpy="0 0 0" xyz="0 0 0" />
            <geometry>
                <mesh filename="meshes/r300/meshes/dae/base_link.dae" />
            </geometry>
        </visual>
        <collision>
            <origin rpy="1.5707963 0 0" xyz="0 0 -0.060" />
            <geometry>
                <mesh filename="meshes/r300/meshes/stl/base_link.stl" />
            </geometry>
        </collision>
        <!--<collision>
      <origin xyz="${Joint_ZERO} ${Joint_ZERO} ${Joint_ZERO}.017" rpy="${Joint_ZERO} ${Joint_ZERO} ${Joint_ZERO}" />
      <geometry>
       <box size="0.001 0.001 0.001" />
      </geometry>
    </collision>-->
    </link>
    <link name="left_wheel_link">
        <visual>
            <origin rpy="0 0 0" xyz="0 0 0" />
            <geometry>
                <mesh filename="meshes/r300/meshes/stl/wheel.stl" />
            </geometry>
            <material name="black">
                <color rgba="0.0 0.0 0.0 1.0" />
            </material>
        </visual>
        <collision>
            <origin rpy="0 0 0" xyz="0 0 0" />
            <geometry>
                <mesh filename="meshes/r300/meshes/stl/wheel.stl" />
            </geometry>
            <material name="black">
                <color rgba="0.0 0.0 0.0 1.0" />
            </material>
        </collision>
        <inertial>
            <mass value="0.1" />
            <origin xyz="0 0 0" rpy="0 0 0" />
            <inertia ixx="0.03" iyy="0.03" izz="0.03" ixy="0.0" ixz="0.0" iyz="0.0" />
        </inertial>
    </link>
    <joint name="left_wheel_joint" type="continuous">
        <origin rpy="-1.5707963 0.343792057554545 3.1415926" xyz="0 0.2565 0.03" />
        <parent link="base_link" />
        <child link="left_wheel_link" />
        <axis xyz="0 0 -1" />
    </joint>
    <link name="right_wheel_link">
        <visual>
            <origin rpy="0 0 0" xyz="0 0 0" />
            <geometry>
                <mesh filename="meshes/r300/meshes/stl/wheel.stl" />
            </geometry>
            <material name="black">
                <color rgba="0.0 0.0 0.0 1.0" />
            </material>
        </visual>
        <collision>
            <origin rpy="0 0 0" xyz="0 0 0" />
            <geometry>
                <mesh filename="meshes/r300/meshes/stl/wheel.stl" />
            </geometry>
            <material name="black">
                <color rgba="0.0 0.0 0.0 1.0" />
            </material>
        </collision>
        <inertial>
            <mass value="0.1" />
            <origin xyz="0 0 0" rpy="0 0 0" />
            <inertia ixx="0.03" iyy="0.03" izz="0.03" ixy="0.0" ixz="0.0" iyz="0.0" />
        </inertial>
    </link>
    <joint name="right_wheel_joint" type="continuous">
        <origin rpy="1.5707963 1.11682274353561 3.1415926" xyz="0 -0.2565 0.03" />
        <parent link="base_link" />
        <child link="right_wheel_link" />
        <axis xyz="0 0 1" />
    </joint>
    <link name="imu_link" />
    <joint name="imu_joint" type="fixed">
        <origin rpy="0 0 0" xyz="0.3512 0.1309 0.205" />
        <parent link="base_link" />
        <child link="imu_link" />
    </joint>
    <link name="sonar_link1" />
    <joint name="sonar1_joint" type="fixed">
        <origin rpy="0 0  1.5707963" xyz="0.3575 0.3277 0.23735" />
        <parent link="base_link" />
        <child link="sonar_link1" />
    </joint>
    <link name="sonar_link2" />
    <joint name="sonar2_joint" type="fixed">
        <origin rpy="0 0 0" xyz="0.5053 0.2265 0.23735" />
        <parent link="base_link" />
        <child link="sonar_link2" />
    </joint>
    <link name="sonar_link3" />
    <joint name="sonar3_joint" type="fixed">
        <origin rpy="0 0 0" xyz="0.5053 -0.2265 0.23735" />
        <parent link="base_link" />
        <child link="sonar_link3" />
    </joint>
    <link name="sonar_link4" />
    <joint name="sonar4_joint" type="fixed">
        <origin rpy="0 0 -1.5707963" xyz="0.3575 -0.3277 0.23735" />
        <parent link="base_link" />
        <child link="sonar_link4" />
    </joint>
    <link name="camera_link" />
    <joint name="camera_joint" type="fixed">
        <origin rpy="0 0.2618 0" xyz="0.49757 0 0.10785" />
        <parent link="base_link" />
        <child link="camera_link" />
    </joint>
    <link name="front_laser">
        <!--inertial>
      <mass value="0.0001" />
      <origin xyz="${Joint_ZERO} ${Joint_ZERO} ${Joint_ZERO}" />
      <inertia ixx="0.0001" ixy="0.0" ixz="0.0"
               iyy="0.0001" iyz="0.0"
               izz="0.0001" />
    </inertial>
    <visual>
      <origin xyz="0 0 -0.10383" rpy="${Joint_ZERO} ${Joint_ZERO} ${Joint_ZERO}" />
      <geometry>
        <mesh filename="meshes/ir100_description/meshes/laser${POINT_S}" />
      </geometry>
      <material name="OffWhite" />
    </visual-->
        <!--<collision>
      <origin xyz="${Joint_ZERO} ${Joint_ZERO} ${Joint_ZERO}.017" rpy="${Joint_ZERO} ${Joint_ZERO} ${Joint_ZERO}" />
      <geometry>
       <box size="0.001 0.001 0.001" />
      </geometry>
    </collision>-->
    </link>
    <joint name="front_laser_joint" type="fixed">
        <origin rpy="0 0 0.7854" xyz="0.44576 0.27076 0.17794" />
        <parent link="base_link" />
        <child link="front_laser" />
    </joint>
    <link name="rear_laser">
        <!--inertial>
      <mass value="0.0001" />
      <origin xyz="${Joint_ZERO} ${Joint_ZERO} ${Joint_ZERO}" />
      <inertia ixx="0.0001" ixy="0.0" ixz="0.0"
               iyy="0.0001" iyz="0.0"
               izz="0.0001" />
    </inertial>
    <visual>
      <origin xyz="0 0 -0.10383" rpy="${Joint_ZERO} ${Joint_ZERO} ${Joint_ZERO}" />
      <geometry>
        <mesh filename="meshes/ir100_description/meshes/laser${POINT_S}" />
      </geometry>
      <material name="OffWhite" />
    </visual-->
        <!--<collision>
      <origin xyz="${Joint_ZERO} ${Joint_ZERO} ${Joint_ZERO}.017" rpy="${Joint_ZERO} ${Joint_ZERO} ${Joint_ZERO}" />
      <geometry>
       <box size="0.001 0.001 0.001" />
      </geometry>
    </collision>-->
    </link>
    <joint name="rear_laser_joint" type="fixed">
        <origin rpy="0 0  -2.3562" xyz="-0.44576 -0.27076 0.17794" />
        <parent link="base_link" />
        <child link="rear_laser" />
    </joint>
    <link name="support_plate_link">
        <inertial>
            <origin rpy="0 0 0" xyz="-0.00769879818929481 0.00591943920213681 0.000775754892935535" />
            <mass value="0.0150075223078031" />
            <inertia ixx="0.000401244716356583" ixy="1.96406862826253E-07" ixz="-1.97369161903718E-06" iyy="0.0013476472579277" iyz="-3.58558233759945E-08" izz="0.000946762375531491" />
        </inertial>
        <visual>
            <origin rpy="0 0 0" xyz="0 0 0" />
            <geometry>
                <mesh filename="meshes/r300/meshes/dae/support_plate_link.dae" />
            </geometry>
            <material name="">
                <color rgba="0.698039215686274 0.698039215686274 0.698039215686274 1" />
            </material>
        </visual>
        <collision>
            <origin rpy="0 0 0" xyz="0 0 0" />
            <geometry>
                <mesh filename="meshes/r300/meshes/stl/support_plate_link.stl" />
            </geometry>
        </collision>
    </link>
    <joint name="joint_support_plate" type="fixed">
        <origin rpy="1.5707963  0 0" xyz="0 0  0.27122" />
        <parent link="base_link" />
        <child link="support_plate_link" />
        <axis xyz="0 0 0" />
    </joint>
    <link name="sound_link">
        <inertial>
            <origin rpy="0 0 0" xyz="7.064E-08 1.9887E-05 0.0054783" />
            <mass value="0.082264" />
            <inertia ixx="8.8836E-05" ixy="9.9348E-11" ixz="-5.4065E-11" iyy="0.0001422" iyz="3.242E-06" izz="5.839E-05" />
        </inertial>
        <visual>
            <origin rpy="0 0 0" xyz="0 0 0" />
            <geometry>
                <mesh filename="meshes/r300/meshes/dae/sound_link.dae" />
            </geometry>
            <material name="">
                <color rgba="0.75294 0.75294 0.75294 1" />
            </material>
        </visual>
        <collision>
            <origin rpy="0 0 0" xyz="0 0 0" />
            <geometry>
                <mesh filename="meshes/r300/meshes/stl/sound_link.stl" />
            </geometry>
        </collision>
    </link>
    <joint name="joint_sound" type="fixed">
        <origin rpy="1.5707963 1.5707963 0" xyz="0.441 0.091 0" />
        <parent link="support_plate_link" />
        <child link="sound_link" />
        <axis xyz="0 0 0" />
    </joint>
    <link name="power_link">
        <inertial>
            <origin rpy="0 0 0" xyz="-0.16763 -0.24089 0.0093517" />
            <mass value="80.118" />
            <inertia ixx="1.9178" ixy="-0.099825" ixz="0.0026768" iyy="4.1251" iyz="0.0035351" izz="5.2847" />
        </inertial>
        <visual>
            <origin rpy="0 0 0" xyz="0 0 0" />
            <geometry>
                <mesh filename="meshes/r300/meshes/dae/power_link.dae" />
            </geometry>
            <material name="">
                <color rgba="0.75294 0.75294 0.75294 1" />
            </material>
        </visual>
        <collision>
            <origin rpy="0 0 0" xyz="0 0 0" />
            <geometry>
                <mesh filename="meshes/r300/meshes/stl/power_link.stl" />
            </geometry>
        </collision>
    </link>
    <joint name="joint_power" type="fixed">
        <origin rpy="-1.5707963 0 -1.5707963" xyz="-0.2305 0.2025 -0.2325" />
        <parent link="support_plate_link" />
        <child link="power_link" />
        <axis xyz="0 0 0" />
    </joint>
    <link name="rear_lower_body_link">
        <inertial>
            <origin rpy="0 0 0" xyz="-0.15248 0.00011192 0.23921" />
            <mass value="2.0145" />
            <inertia ixx="0.10489" ixy="1.7756E-05" ixz="-0.0053272" iyy="0.051964" iyz="2.3902E-05" izz="0.075459" />
        </inertial>
        <visual>
            <origin rpy="0 0 0" xyz="0 0 0" />
            <geometry>
               <mesh filename="meshes/r300/meshes/dae/rear_lower_body_link.dae" />
            </geometry>
            <material name="">
                <color rgba="0.69804 0.69804 0.69804 1" />
            </material>
        </visual>
        <collision>
            <origin rpy="0 0 0" xyz="0 0 0" />
            <geometry>
                <mesh filename="meshes/r300/meshes/stl/rear_lower_body_link.stl" />
            </geometry>
        </collision>
    </link>
    <joint name="joint_rear_lower_body_link" type="fixed">
        <origin rpy="-1.5707963 0 0" xyz="0.22 0 0" />
        <parent link="support_plate_link" />
        <child link="rear_lower_body_link" />
        <axis xyz="0 0 0" />
    </joint>
    <link name="front_low_body_link">
        <inertial>
            <origin rpy="0 0 0" xyz="0.15746 -2.7173E-05 0.23455" />
            <mass value="2.1587" />
            <inertia ixx="0.11236" ixy="6.5356E-06" ixz="0.0063318" iyy="0.058122" iyz="8.799E-06" izz="0.078686" />
        </inertial>
        <visual>
            <origin rpy="0 0 0" xyz="0 0 0" />
            <geometry>
                <mesh filename="meshes/r300/meshes/dae/front_low_body_link.dae" />
            </geometry>
            <material name="">
                <color rgba="0.69804 0.69804 0.69804 1" />
            </material>
        </visual>
        <collision>
            <origin rpy="0 0 0" xyz="0 0 0" />
            <geometry>
                <mesh filename="meshes/r300/meshes/stl/front_low_body_link.stl" />
            </geometry>
        </collision>
    </link>
    <joint name="joint_front_low_body" type="fixed">
        <origin rpy="-1.5707963 0 0" xyz="0.219572 0 0" />
        <parent link="support_plate_link" />
        <child link="front_low_body_link" />
        <axis xyz="0 0 0" />
    </joint>
    <link name="battery_cover_link">
        <inertial>
            <origin rpy="0 0 0" xyz="0.0006734 0.42928 -3.1718E-05" />
            <mass value="7.5589" />
            <inertia ixx="0.62329" ixy="-0.0023787" ixz="-7.1765E-05" iyy="0.50548" iyz="-9.1039E-05" izz="0.84513" />
        </inertial>
        <visual>
            <origin rpy="0 0 0" xyz="0 0 0" />
            <geometry>
                <mesh filename="meshes/r300/meshes/dae/battery_cover_link.dae" />
            </geometry>
            <material name="">
                <color rgba="0.75294 0.75294 0.75294 1" />
            </material>
        </visual>
        <collision>
            <origin rpy="0 0 0" xyz="0 0 0" />
            <geometry>
                <mesh filename="meshes/r300/meshes/stl/battery_cover_link.stl" />
            </geometry>
        </collision>
    </link>
    <joint name="joint_battery_cover" type="fixed">
        <origin rpy="0 -1.5707963 0" xyz="-0.22143 0.012242 0" />
        <parent link="support_plate_link" />
        <child link="battery_cover_link" />
        <axis xyz="0 0 0" />
    </joint>
    <link name="fixed_frame_link">
        <inertial>
            <origin rpy="0 0 0" xyz="0.0415891906441214 -0.11965106670571 9.51748813968201E-07" />
            <mass value="4.28692965567898" />
            <inertia ixx="0.031165640285231" ixy="0.000599137513617035" ixz="-2.54061506448287E-08" iyy="0.02365275729269" iyz="6.20699851504226E-07" izz="0.0226263403429132" />
        </inertial>
        <visual>
            <origin rpy="0 0 0" xyz="0 0 0" />
            <geometry>
                <mesh filename="meshes/r300/meshes/dae/fixed_frame_link.dae" />
            </geometry>
            <material name="">
                <color rgba="0.752941176470588 0.752941176470588 0.752941176470588 1" />
            </material>
        </visual>
        <collision>
            <origin rpy="0 0 0" xyz="0 0 0" />
            <geometry>
                <mesh filename="meshes/r300/meshes/stl/fixed_frame_link.stl" />
            </geometry>
        </collision>
    </link>
    <joint name="joint_fixed_frame" type="fixed">
        <origin rpy="-1.5707963 0 3.1415926" xyz="0 0 0.35" />
        <parent link="lifting_rod_link" />
        <child link="fixed_frame_link" />
        <axis xyz="0 0 0" />
    </joint>
    <link name="rear_upper_body_link">
        <inertial>
            <origin rpy="0 0 0" xyz="0.10517 -0.16914 0.00019511" />
            <mass value="1.3101" />
            <inertia ixx="0.076077" ixy="-0.0030685" ixz="1.7592E-05" iyy="0.020111" iyz="6.197E-05" izz="0.063754" />
        </inertial>
        <visual>
            <origin rpy="0 0 0" xyz="0 0 0" />
            <geometry>
                <mesh filename="meshes/r300/meshes/dae/rear_upper_body_link.dae" />
            </geometry>
            <material name="">
                <color rgba="0.69804 0.69804 0.69804 1" />
            </material>
        </visual>
        <collision>
            <origin rpy="0 0 0" xyz="0 0 0" />
            <geometry>
                <mesh filename="meshes/r300/meshes/stl/rear_upper_body_link.stl" />
            </geometry>
        </collision>
    </link>
    <joint name="joint_rear_upper_body" type="fixed">
        <origin rpy="0 -1.5707963 3.1415926" xyz="0 -0.119469 0" />
        <parent link="fixed_frame_link" />
        <child link="rear_upper_body_link" />
        <axis xyz="0 0 0" />
    </joint>
    <link name="front_upper_body_link">
        <inertial>
            <origin rpy="0 0 0" xyz="0.10517 -0.16914 0.00019511" />
            <mass value="1.3101" />
            <inertia ixx="0.076077" ixy="-0.0030685" ixz="1.7592E-05" iyy="0.020111" iyz="6.197E-05" izz="0.063754" />
        </inertial>
        <visual>
            <origin rpy="0 0 0" xyz="0 0 0" />
            <geometry>
                <mesh filename="meshes/r300/meshes/dae/front_upper_body_link.dae" />
            </geometry>
            <material name="">
                <color rgba="0.69804 0.69804 0.69804 1" />
            </material>
        </visual>
        <collision>
            <origin rpy="0 0 0" xyz="0 0 0" />
            <geometry>
                <mesh filename="meshes/r300/meshes/stl/front_upper_body_link.stl" />
            </geometry>
        </collision>
    </link>
    <joint name="joint_front_upper_body" type="fixed">
        <origin rpy="0 1.5707963 3.1415926" xyz="0 -0.119469 0" />
        <parent link="fixed_frame_link" />
        <child link="front_upper_body_link" />
        <axis xyz="0 0 0" />
    </joint>
    <transmission name="trans_joint_lifting_rod">
        <type>transmission_interface/SimpleTransmission</type>
        <joint name="joint_lifting_rod">
            <hardwareInterface>hardware_interface/EffortJointInterface</hardwareInterface>
        </joint>
        <actuator name="joint_lifting_rod_motor">
            <hardwareInterface>hardware_interface/EffortJointInterface</hardwareInterface>
            <mechanicalReduction>1</mechanicalReduction>
        </actuator>
    </transmission>
    <transmission name="trans_joint_driving_gear">
        <type>transmission_interface/SimpleTransmission</type>
        <joint name="joint_driving_gear">
            <hardwareInterface>hardware_interface/EffortJointInterface</hardwareInterface>
        </joint>
        <actuator name="joint_driving_gear_motor">
            <hardwareInterface>hardware_interface/EffortJointInterface</hardwareInterface>
            <mechanicalReduction>1</mechanicalReduction>
        </actuator>
    </transmission>
    <transmission name="trans_joint_driven_gear">
        <type>transmission_interface/SimpleTransmission</type>
        <joint name="joint_driven_gear">
            <hardwareInterface>hardware_interface/EffortJointInterface</hardwareInterface>
        </joint>
        <actuator name="joint_driven_gear_motor">
            <hardwareInterface>hardware_interface/EffortJointInterface</hardwareInterface>
            <mechanicalReduction>1</mechanicalReduction>
        </actuator>
    </transmission>
    <transmission name="trans_joint_PTZ_head">
        <type>transmission_interface/SimpleTransmission</type>
        <joint name="joint_PTZ_head">
            <hardwareInterface>hardware_interface/EffortJointInterface</hardwareInterface>
        </joint>
        <actuator name="joint_PTZ_head_motor">
            <hardwareInterface>hardware_interface/EffortJointInterface</hardwareInterface>
            <mechanicalReduction>1</mechanicalReduction>
        </actuator>
    </transmission>
    <transmission name="trans_joint_PTZ_axis">
        <type>transmission_interface/SimpleTransmission</type>
        <joint name="joint_PTZ_axis">
            <hardwareInterface>hardware_interface/EffortJointInterface</hardwareInterface>
        </joint>
        <actuator name="joint_PTZ_axis_motor">
            <hardwareInterface>hardware_interface/EffortJointInterface</hardwareInterface>
            <mechanicalReduction>1</mechanicalReduction>
        </actuator>
    </transmission>
    <transmission name="trans_left_wheel_joint">
        <type>transmission_interface/SimpleTransmission</type>
        <joint name="left_wheel_joint">
            <hardwareInterface>hardware_interface/EffortJointInterface</hardwareInterface>
        </joint>
        <actuator name="left_wheel_joint_motor">
            <hardwareInterface>hardware_interface/EffortJointInterface</hardwareInterface>
            <mechanicalReduction>1</mechanicalReduction>
        </actuator>
    </transmission>
    <transmission name="trans_right_wheel_joint">
        <type>transmission_interface/SimpleTransmission</type>
        <joint name="right_wheel_joint">
            <hardwareInterface>hardware_interface/EffortJointInterface</hardwareInterface>
        </joint>
        <actuator name="right_wheel_joint_motor">
            <hardwareInterface>hardware_interface/EffortJointInterface</hardwareInterface>
            <mechanicalReduction>1</mechanicalReduction>
        </actuator>
    </transmission>
    <gazebo>
        <plugin name="gazebo_ros_control">
            <robotNamespace>/</robotNamespace>
        </plugin>
    </gazebo>
</robot>

