<?xml version="1.0" encoding="utf-8"?>
<!-- This URDF was automatically created by SolidWorks to URDF Exporter! Originally created by Stephen Brawner (brawner@gmail.com) 
     Commit Version: 1.6.0-1-g15f4949  Build Version: 1.6.7594.29634
     For more information, please see http://wiki.ros.org/sw_urdf_exporter -->
<robot
  name="dh3_urdf">
  <link
    name="base_Link">
    <inertial>
      <origin
        xyz="-0.000222201146896917 2.99284922239407E-06 0.0365598116000577"
        rpy="0 0 0" />
      <mass
        value="0.359681668644718" />
      <inertia
        ixx="0.000426094138511423"
        ixy="-3.47685971240899E-10"
        ixz="-3.70902449457946E-07"
        iyy="0.000421830861136388"
        iyz="-1.73791620761484E-10"
        izz="0.000552700185384758" />
    </inertial>
    <visual>
      <origin
        xyz="0 0 0"
        rpy="0 0 0" />
      <geometry>
        <mesh
          filename="package://meshes/base_Link.STL" />
      </geometry>
      <material
        name="">
        <color
          rgba="1 1 1 1" />
      </material>
    </visual>
    <collision>
      <origin
        xyz="0 0 0"
        rpy="0 0 0" />
      <geometry>
        <mesh
          filename="package://meshes/base_Link.STL" />
      </geometry>
    </collision>
  </link>
  <link
    name="finger1_base_Link">
    <inertial>
      <origin
        xyz="-0.000601794667080963 -0.00110288755052515 0.00521005597269414"
        rpy="0 0 0" />
      <mass
        value="0.00832299911583519" />
      <inertia
        ixx="9.16214830766921E-07"
        ixy="2.57171997873981E-08"
        ixz="1.43130193804266E-08"
        iyy="1.14280462688504E-06"
        iyz="5.78075867067328E-08"
        izz="1.77055158585085E-06" />
    </inertial>
    <visual>
      <origin
        xyz="0 0 0"
        rpy="0 0 0" />
      <geometry>
        <mesh
          filename="package://meshes/finger1_base_Link.STL" />
      </geometry>
      <material
        name="">
        <color
          rgba="1 1 1 1" />
      </material>
    </visual>
    <collision>
      <origin
        xyz="0 0 0"
        rpy="0 0 0" />
      <geometry>
        <mesh
          filename="package://meshes/finger1_base_Link.STL" />
      </geometry>
    </collision>
  </link>
  <joint
    name="finger1_base_joint"
    type="revolute">
    <origin
      xyz="-0.0161724988655456 0.0279961367597022 0.105"
      rpy="0 0 0.523598783277495" />
    <parent
      link="base_Link" />
    <child
      link="finger1_base_Link" />
    <axis
      xyz="0 0 -1" />
    <limit
      lower="-1"
      upper="0.54"
      effort="100"
      velocity="100" />
  </joint>
  <link
    name="finger1_Link">
    <inertial>
      <origin
        xyz="0.0210050434938139 0.012249999999974 0.0178290357798672"
        rpy="0 0 0" />
      <mass
        value="0.00557906977988049" />
      <inertia
        ixx="8.99405333082292E-07"
        ixy="9.82637628153793E-19"
        ixz="-5.95537945974777E-07"
        iyy="1.3061675562027E-06"
        iyz="6.37604051045675E-19"
        izz="1.24905466077277E-06" />
    </inertial>
    <visual>
      <origin
        xyz="0 0 0"
        rpy="0 0 0" />
      <geometry>
        <mesh
          filename="package://meshes/finger1_Link.STL" />
      </geometry>
      <material
        name="">
        <color
          rgba="0.0549019607843137 0.0549019607843137 0.0549019607843137 1" />
      </material>
    </visual>
    <collision>
      <origin
        xyz="0 0 0"
        rpy="0 0 0" />
      <geometry>
        <mesh
          filename="package://meshes/finger1_Link.STL" />
      </geometry>
    </collision>
  </link>
  <joint
    name="finger1_joint"
    type="revolute">
    <origin
      xyz="0.01225 -0.0081568 0.0175"
      rpy="0 0 1.5708" />
    <parent
      link="finger1_base_Link" />
    <child
      link="finger1_Link" />
    <axis
      xyz="0 -1 0" />
    <limit
      lower="0"
      upper="1.16"
      effort="100"
      velocity="100" />
  </joint>
  <link
    name="finger1_tip_Link">
    <inertial>
      <origin
        xyz="0.000977109926666546 0.0123819370127123 0.0136590907193947"
        rpy="0 0 0" />
      <mass
        value="0.0107564294883422" />
      <inertia
        ixx="1.48949781713587E-06"
        ixy="-7.10872889918193E-09"
        ixz="1.38025837549055E-07"
        iyy="1.35009809053808E-06"
        iyz="1.24264254163864E-08"
        izz="4.77788297009959E-07" />
    </inertial>
    <visual>
      <origin
        xyz="0 0 0"
        rpy="0 0 0" />
      <geometry>
        <mesh
          filename="package://meshes/finger1_tip_Link.STL" />
      </geometry>
      <material
        name="">
        <color
          rgba="1 1 1 1" />
      </material>
    </visual>
    <collision>
      <origin
        xyz="0 0 0"
        rpy="0 0 0" />
      <geometry>
        <mesh
          filename="package://meshes/finger1_tip_Link.STL" />
      </geometry>
    </collision>
  </link>
  <joint
    name="finger1_tip_joint"
    type="revolute">
    <origin
      xyz="0.044029 0 0.032962"
      rpy="0 0 0" />
    <parent
      link="finger1_Link" />
    <child
      link="finger1_tip_Link" />
    <axis
      xyz="0 -1 0" />
    <limit
      lower="-1"
      upper="1"
      effort="100"
      velocity="100" />
    <mimic
      joint="finger1_joint"
      multiplier="-1"
      offset="0" />
  </joint>
  <link
    name="finger1_outlet_Link">
    <inertial>
      <origin
        xyz="0.0205745260056277 -0.00269403354044023 0.0154029170399833"
        rpy="0 0 0" />
      <mass
        value="0.00494212097275844" />
      <inertia
        ixx="3.17521820164163E-07"
        ixy="-1.11658813824013E-10"
        ixz="-3.22040978315679E-07"
        iyy="7.52126023069253E-07"
        iyz="-8.36396169396533E-11"
        izz="5.06597025546867E-07" />
    </inertial>
    <visual>
      <origin
        xyz="0 0 0"
        rpy="0 0 0" />
      <geometry>
        <mesh
          filename="package://meshes/finger1_outlet_Link.STL" />
      </geometry>
      <material
        name="">
        <color
          rgba="1 1 1 1" />
      </material>
    </visual>
    <collision>
      <origin
        xyz="0 0 0"
        rpy="0 0 0" />
      <geometry>
        <mesh
          filename="package://meshes/finger1_outlet_Link.STL" />
      </geometry>
    </collision>
  </link>
  <joint
    name="finger1_outlet_joint"
    type="revolute">
    <origin
      xyz="-0.01035 0.0081568 0.0098929"
      rpy="0 0 1.5708" />
    <parent
      link="finger1_base_Link" />
    <child
      link="finger1_outlet_Link" />
    <axis
      xyz="0 1 0" />
    <limit
      lower="0"
      upper="0"
      effort="0"
      velocity="0" />
    <mimic
      joint="finger1_joint"
      multiplier="-1"
      offset="0" />
  </joint>
  <link
    name="finger2_base_Link">
    <inertial>
      <origin
        xyz="-0.000601794667086514 -0.00110288755052199 0.00521005597269419"
        rpy="0 0 0" />
      <mass
        value="0.00832299911583519" />
      <inertia
        ixx="9.16214830767147E-07"
        ixy="2.57171997885585E-08"
        ixz="1.43130193807236E-08"
        iyy="1.14280462688473E-06"
        iyz="5.78075867066608E-08"
        izz="1.77055158585084E-06" />
    </inertial>
    <visual>
      <origin
        xyz="0 0 0"
        rpy="0 0 0" />
      <geometry>
        <mesh
          filename="package://meshes/finger2_base_Link.STL" />
      </geometry>
      <material
        name="">
        <color
          rgba="1 1 1 1" />
      </material>
    </visual>
    <collision>
      <origin
        xyz="0 0 0"
        rpy="0 0 0" />
      <geometry>
        <mesh
          filename="package://meshes/finger2_base_Link.STL" />
      </geometry>
    </collision>
  </link>
  <joint
    name="finger2_base_joint"
    type="fixed">
    <origin
      xyz="0.032325 0 0.105"
      rpy="0 0 -1.5708" />
    <parent
      link="base_Link" />
    <child
      link="finger2_base_Link" />
    <axis
      xyz="0 0 0" />
  </joint>
  <link
    name="finger2_link">
    <inertial>
      <origin
        xyz="0.021005043493832 0.0122499999999494 0.0178290357798643"
        rpy="0 0 0" />
      <mass
        value="0.00557906977988033" />
      <inertia
        ixx="8.99405333082248E-07"
        ixy="1.40895930945985E-18"
        ixz="-5.95537945974751E-07"
        iyy="1.30616755620265E-06"
        iyz="1.47278790722963E-18"
        izz="1.24905466077276E-06" />
    </inertial>
    <visual>
      <origin
        xyz="0 0 0"
        rpy="0 0 0" />
      <geometry>
        <mesh
          filename="package://meshes/finger2_link.STL" />
      </geometry>
      <material
        name="">
        <color
          rgba="0.0549019607843137 0.0549019607843137 0.0549019607843137 1" />
      </material>
    </visual>
    <collision>
      <origin
        xyz="0 0 0"
        rpy="0 0 0" />
      <geometry>
        <mesh
          filename="package://meshes/finger2_link.STL" />
      </geometry>
    </collision>
  </link>
  <joint
    name="finger2_joint"
    type="revolute">
    <origin
      xyz="0.01225 -0.0081568 0.0175"
      rpy="0 0 1.5708" />
    <parent
      link="finger2_base_Link" />
    <child
      link="finger2_link" />
    <axis
      xyz="0 -1 0" />
    <limit
      lower="0"
      upper="0"
      effort="0"
      velocity="0" />
    <mimic
      joint="finger1_joint"
      multiplier="1"
      offset="0" />
  </joint>
  <link
    name="finger2_tip_Link">
    <inertial>
      <origin
        xyz="0.000977109970519835 0.0123819365363909 0.0136590906877767"
        rpy="0 0 0" />
      <mass
        value="0.0107564295938579" />
      <inertia
        ixx="1.48949781977635E-06"
        ixy="-7.10872109767472E-09"
        ixz="1.38025837268698E-07"
        iyy="1.35009809568266E-06"
        iyz="1.24264681742315E-08"
        izz="4.77788294510709E-07" />
    </inertial>
    <visual>
      <origin
        xyz="0 0 0"
        rpy="0 0 0" />
      <geometry>
        <mesh
          filename="package://meshes/finger2_tip_Link.STL" />
      </geometry>
      <material
        name="">
        <color
          rgba="1 1 1 1" />
      </material>
    </visual>
    <collision>
      <origin
        xyz="0 0 0"
        rpy="0 0 0" />
      <geometry>
        <mesh
          filename="package://meshes/finger2_tip_Link.STL" />
      </geometry>
    </collision>
  </link>
  <joint
    name="finger2_tip_joint"
    type="revolute">
    <origin
      xyz="0.044029 0 0.032962"
      rpy="0 0 0" />
    <parent
      link="finger2_link" />
    <child
      link="finger2_tip_Link" />
    <axis
      xyz="0 -1 0" />
    <limit
      lower="0"
      upper="0"
      effort="0"
      velocity="0" />
    <mimic
      joint="finger1_tip_joint"
      multiplier="1"
      offset="0" />
  </joint>
  <link
    name="finger2_outlet_Link">
    <inertial>
      <origin
        xyz="0.0205745216753029 -0.00269403287328564 0.0154029129942138"
        rpy="0 0 0" />
      <mass
        value="0.00494212190694487" />
      <inertia
        ixx="3.17522151991331E-07"
        ixy="-1.11440245000629E-10"
        ixz="-3.22041349248125E-07"
        iyy="7.52126778397778E-07"
        iyz="-8.34843588255468E-11"
        izz="5.06597462640552E-07" />
    </inertial>
    <visual>
      <origin
        xyz="0 0 0"
        rpy="0 0 0" />
      <geometry>
        <mesh
          filename="package://meshes/finger2_outlet_Link.STL" />
      </geometry>
      <material
        name="">
        <color
          rgba="1 1 1 1" />
      </material>
    </visual>
    <collision>
      <origin
        xyz="0 0 0"
        rpy="0 0 0" />
      <geometry>
        <mesh
          filename="package://meshes/finger2_outlet_Link.STL" />
      </geometry>
    </collision>
  </link>
  <joint
    name="finger2_outlet_joint"
    type="revolute">
    <origin
      xyz="-0.01035 0.0081568 0.0098929"
      rpy="0 0 1.5708" />
    <parent
      link="finger2_base_Link" />
    <child
      link="finger2_outlet_Link" />
    <axis
      xyz="0 1 0" />
    <limit
      lower="0"
      upper="0"
      effort="0"
      velocity="0" />
    <mimic
      joint="finger1_outlet_joint"
      multiplier="1"
      offset="0" />
  </joint>
  <link
    name="finger3_base_Link">
    <inertial>
      <origin
        xyz="-0.000601794667079381 -0.00110288755052597 0.00521005597269403"
        rpy="0 0 0" />
      <mass
        value="0.00832299911583507" />
      <inertia
        ixx="9.16214830766856E-07"
        ixy="2.57171997871098E-08"
        ixz="1.43130193803543E-08"
        iyy="1.1428046268851E-06"
        iyz="5.78075867067519E-08"
        izz="1.77055158585085E-06" />
    </inertial>
    <visual>
      <origin
        xyz="0 0 0"
        rpy="0 0 0" />
      <geometry>
        <mesh
          filename="package://meshes/finger3_base_Link.STL" />
      </geometry>
      <material
        name="">
        <color
          rgba="1 1 1 1" />
      </material>
    </visual>
    <collision>
      <origin
        xyz="0 0 0"
        rpy="0 0 0" />
      <geometry>
        <mesh
          filename="package://meshes/finger3_base_Link.STL" />
      </geometry>
    </collision>
  </link>
  <joint
    name="finger3_base_joint"
    type="revolute">
    <origin
      xyz="-0.016172 -0.028004 0.105"
      rpy="0 0 2.618" />
    <parent
      link="base_Link" />
    <child
      link="finger3_base_Link" />
    <axis
      xyz="0 0 -1" />
    <limit
      lower="0"
      upper="0"
      effort="0"
      velocity="0" />
    <mimic
      joint="finger1_base_joint"
      multiplier="-1"
      offset="0" />
  </joint>
  <link
    name="finger3_Link">
    <inertial>
      <origin
        xyz="0.0210050434938141 0.012249999999974 0.0178290357798672"
        rpy="0 0 0" />
      <mass
        value="0.0055790697798808" />
      <inertia
        ixx="8.99405333082359E-07"
        ixy="9.61461081223117E-19"
        ixz="-5.95537945974827E-07"
        iyy="1.30616755620281E-06"
        iyz="6.24087927058166E-19"
        izz="1.24905466077285E-06" />
    </inertial>
    <visual>
      <origin
        xyz="0 0 0"
        rpy="0 0 0" />
      <geometry>
        <mesh
          filename="package://meshes/finger3_Link.STL" />
      </geometry>
      <material
        name="">
        <color
          rgba="0.0549019607843137 0.0549019607843137 0.0549019607843137 1" />
      </material>
    </visual>
    <collision>
      <origin
        xyz="0 0 0"
        rpy="0 0 0" />
      <geometry>
        <mesh
          filename="package://meshes/finger3_Link.STL" />
      </geometry>
    </collision>
  </link>
  <joint
    name="finger3_joint"
    type="revolute">
    <origin
      xyz="0.0122500000000007 -0.00815677008333035 0.0174999999999995"
      rpy="0 0 1.5707963267949" />
    <parent
      link="finger3_base_Link" />
    <child
      link="finger3_Link" />
    <axis
      xyz="0 -1 0" />
    <limit
      lower="0"
      upper="0"
      effort="0"
      velocity="0" />
    <mimic
      joint="finger1_joint"
      multiplier="1"
      offset="0" />
  </joint>
  <link
    name="finger3_tip_Link">
    <inertial>
      <origin
        xyz="0.000977114977738613 0.0123819369789457 0.01365909502715"
        rpy="0 0 0" />
      <mass
        value="0.0107564399961694" />
      <inertia
        ixx="1.48949935780095E-06"
        ixy="-7.10872801793197E-09"
        ixz="1.38025629536651E-07"
        iyy="1.35009963358183E-06"
        iyz="1.2426443300764E-08"
        izz="4.77788392346636E-07" />
    </inertial>
    <visual>
      <origin
        xyz="0 0 0"
        rpy="0 0 0" />
      <geometry>
        <mesh
          filename="package://meshes/finger3_tip_Link.STL" />
      </geometry>
      <material
        name="">
        <color
          rgba="1 1 1 1" />
      </material>
    </visual>
    <collision>
      <origin
        xyz="0 0 0"
        rpy="0 0 0" />
      <geometry>
        <mesh
          filename="package://meshes/finger3_tip_Link.STL" />
      </geometry>
    </collision>
  </link>
  <joint
    name="finger3_tip_joint"
    type="revolute">
    <origin
      xyz="0.044029 0 0.032962"
      rpy="0 0 0" />
    <parent
      link="finger3_Link" />
    <child
      link="finger3_tip_Link" />
    <axis
      xyz="0 -1 0" />
    <limit
      lower="0"
      upper="0"
      effort="0"
      velocity="0" />
    <mimic
      joint="finger1_tip_joint"
      multiplier="1"
      offset="0" />
  </joint>
  <link
    name="finger3_outlet_Link">
    <inertial>
      <origin
        xyz="0.0205745375238259 -0.00269403304520632 0.0154029215009596"
        rpy="0 0 0" />
      <mass
        value="0.00494212514535466" />
      <inertia
        ixx="3.17522114051902E-07"
        ixy="-1.11543432026918E-10"
        ixz="-3.22041207812167E-07"
        iyy="7.52126509554002E-07"
        iyz="-8.35643256488424E-11"
        izz="5.0659720155034E-07" />
    </inertial>
    <visual>
      <origin
        xyz="0 0 0"
        rpy="0 0 0" />
      <geometry>
        <mesh
          filename="package://meshes/finger3_outlet_Link.STL" />
      </geometry>
      <material
        name="">
        <color
          rgba="1 1 1 1" />
      </material>
    </visual>
    <collision>
      <origin
        xyz="0 0 0"
        rpy="0 0 0" />
      <geometry>
        <mesh
          filename="package://meshes/finger3_outlet_Link.STL" />
      </geometry>
    </collision>
  </link>
  <joint
    name="finger3_outlet_joint"
    type="revolute">
    <origin
      xyz="-0.01035 0.0081568 0.0098929"
      rpy="0 0 1.5708" />
    <parent
      link="finger3_base_Link" />
    <child
      link="finger3_outlet_Link" />
    <axis
      xyz="0 1 0" />
    <limit
      lower="0"
      upper="0"
      effort="0"
      velocity="0" />
    <mimic
      joint="finger1_outlet_joint"
      multiplier="1"
      offset="0" />
  </joint>
</robot>
