<?xml version="1.0" ?>
<!-- =================================================================================== -->
<!-- |    This document was autogenerated by xacro from /home/fotios/shadow/src/sr_interface/sr_multi_moveit/sr_box_ur10_moveit_config/config/ra_ur10_with_box.urdf.xacro | -->
<!-- |    EDITING THIS FILE BY HAND IS NOT RECOMMENDED                                 | -->
<!-- =================================================================================== -->
<robot name="ursr">
  <link name="ra_base_link">
    <visual>
      <origin rpy="0 0 3.14159265359" xyz="0 0 0"/>
      <geometry>
        <mesh filename="package://ur_description/meshes/ur10/visual/base.dae"/>
      </geometry>
      <material name="LightGrey">
        <color rgba="0.7 0.7 0.7 1.0"/>
      </material>
    </visual>
    <collision>
      <origin rpy="0 0 3.14159265359" xyz="0 0 0"/>
      <geometry>
        <mesh filename="package://ur_description/meshes/ur10/collision/base.stl"/>
      </geometry>
    </collision>
    <inertial>
      <mass value="4.0"/>
      <origin rpy="0 0 0" xyz="0.0 0.0 0.0"/>
      <inertia ixx="0.0061063308908" ixy="0.0" ixz="0.0" iyy="0.0061063308908" iyz="0.0" izz="0.01125"/>
    </inertial>
  </link>
  <joint name="ra_shoulder_pan_joint" type="revolute">
    <parent link="ra_base_link"/>
    <child link="ra_shoulder_link"/>
    <origin rpy="0 0 3.14159265359" xyz="0 0 0.1273"/>
    <axis xyz="0 0 1"/>
    <limit effort="330.0" lower="-6.28318530718" upper="6.28318530718" velocity="2.16"/>
    <dynamics damping="0.0" friction="0.0"/>
  </joint>
  <link name="ra_shoulder_link">
    <visual>
      <origin rpy="0 0 3.14159265359" xyz="0 0 0"/>
      <geometry>
        <mesh filename="package://ur_description/meshes/ur10/visual/shoulder.dae"/>
      </geometry>
      <material name="LightGrey">
        <color rgba="0.7 0.7 0.7 1.0"/>
      </material>
    </visual>
    <collision>
      <origin rpy="0 0 3.14159265359" xyz="0 0 0"/>
      <geometry>
        <mesh filename="package://ur_description/meshes/ur10/collision/shoulder.stl"/>
      </geometry>
    </collision>
    <inertial>
      <mass value="7.778"/>
      <origin rpy="0 0 0" xyz="0.0 0.0 0.0"/>
      <inertia ixx="0.0314743125769" ixy="0.0" ixz="0.0" iyy="0.0314743125769" iyz="0.0" izz="0.021875625"/>
    </inertial>
  </link>
  <joint name="ra_shoulder_lift_joint" type="revolute">
    <parent link="ra_shoulder_link"/>
    <child link="ra_upper_arm_link"/>
    <origin rpy="1.570796327 0 0" xyz="0 0 0"/>
    <axis xyz="0 0 1"/>
    <limit effort="330.0" lower="-6.28318530718" upper="6.28318530718" velocity="2.16"/>
    <dynamics damping="0.0" friction="0.0"/>
  </joint>
  <link name="ra_upper_arm_link">
    <visual>
      <origin rpy="1.57079632679 0 -1.57079632679" xyz="0 0 0.220941"/>
      <geometry>
        <mesh filename="package://ur_description/meshes/ur10/visual/upperarm.dae"/>
      </geometry>
      <material name="LightGrey">
        <color rgba="0.7 0.7 0.7 1.0"/>
      </material>
    </visual>
    <collision>
      <origin rpy="1.57079632679 0 -1.57079632679" xyz="0 0 0.220941"/>
      <geometry>
        <mesh filename="package://ur_description/meshes/ur10/collision/upperarm.stl"/>
      </geometry>
    </collision>
    <inertial>
      <mass value="12.93"/>
      <origin rpy="0 1.57079632679 0" xyz="-0.306 0.0 0.175"/>
      <inertia ixx="0.421753803798" ixy="0.0" ixz="0.0" iyy="0.421753803798" iyz="0.0" izz="0.036365625"/>
    </inertial>
  </link>
  <joint name="ra_elbow_joint" type="revolute">
    <parent link="ra_upper_arm_link"/>
    <child link="ra_forearm_link"/>
    <origin rpy="0 0 0" xyz="-0.612 0 0"/>
    <axis xyz="0 0 1"/>
    <limit effort="150.0" lower="-3.14159265359" upper="3.14159265359" velocity="3.15"/>
    <dynamics damping="0.0" friction="0.0"/>
  </joint>
  <link name="ra_forearm_link">
    <visual>
      <origin rpy="1.57079632679 0 -1.57079632679" xyz="0 0 0.049042"/>
      <geometry>
        <mesh filename="package://ur_description/meshes/ur10/visual/forearm.dae"/>
      </geometry>
      <material name="LightGrey">
        <color rgba="0.7 0.7 0.7 1.0"/>
      </material>
    </visual>
    <collision>
      <origin rpy="1.57079632679 0 -1.57079632679" xyz="0 0 0.049042"/>
      <geometry>
        <mesh filename="package://ur_description/meshes/ur10/collision/forearm.stl"/>
      </geometry>
    </collision>
    <inertial>
      <mass value="3.87"/>
      <origin rpy="0 1.57079632679 0" xyz="-0.306 0.0 0.049042"/>
      <inertia ixx="0.111069694097" ixy="0.0" ixz="0.0" iyy="0.111069694097" iyz="0.0" izz="0.010884375"/>
    </inertial>
  </link>
  <joint name="ra_wrist_1_joint" type="revolute">
    <parent link="ra_forearm_link"/>
    <child link="ra_wrist_1_link"/>
    <origin rpy="0 0 0" xyz="-0.5723 0 0.163941"/>
    <axis xyz="0 0 1"/>
    <limit effort="54.0" lower="-6.28318530718" upper="6.28318530718" velocity="3.2"/>
    <dynamics damping="0.0" friction="0.0"/>
  </joint>
  <link name="ra_wrist_1_link">
    <visual>
      <origin rpy="1.57079632679 0 0" xyz="0 0 -0.1149"/>
      <geometry>
        <mesh filename="package://ur_description/meshes/ur10/visual/wrist1.dae"/>
      </geometry>
      <material name="LightGrey">
        <color rgba="0.7 0.7 0.7 1.0"/>
      </material>
    </visual>
    <collision>
      <origin rpy="1.57079632679 0 0" xyz="0 0 -0.1149"/>
      <geometry>
        <mesh filename="package://ur_description/meshes/ur10/collision/wrist1.stl"/>
      </geometry>
    </collision>
    <inertial>
      <mass value="1.96"/>
      <origin rpy="0 0 0" xyz="0.0 0.0 0.0"/>
      <inertia ixx="0.00494270805625" ixy="0.0" ixz="0.0" iyy="0.00494270805625" iyz="0.0" izz="0.0055125"/>
    </inertial>
  </link>
  <joint name="ra_wrist_2_joint" type="revolute">
    <parent link="ra_wrist_1_link"/>
    <child link="ra_wrist_2_link"/>
    <origin rpy="1.570796327 0 0" xyz="0 -0.1157 -2.37304666792e-11"/>
    <axis xyz="0 0 1"/>
    <limit effort="54.0" lower="-6.28318530718" upper="6.28318530718" velocity="3.2"/>
    <dynamics damping="0.0" friction="0.0"/>
  </joint>
  <link name="ra_wrist_2_link">
    <visual>
      <origin rpy="0 0 0" xyz="0 0 -0.1158"/>
      <geometry>
        <mesh filename="package://ur_description/meshes/ur10/visual/wrist2.dae"/>
      </geometry>
      <material name="LightGrey">
        <color rgba="0.7 0.7 0.7 1.0"/>
      </material>
    </visual>
    <collision>
      <origin rpy="0 0 0" xyz="0 0 -0.1158"/>
      <geometry>
        <mesh filename="package://ur_description/meshes/ur10/collision/wrist2.stl"/>
      </geometry>
    </collision>
    <inertial>
      <mass value="1.96"/>
      <origin rpy="0 0 0" xyz="0.0 0.0 0.0"/>
      <inertia ixx="0.00414471887545" ixy="0.0" ixz="0.0" iyy="0.00414471887545" iyz="0.0" izz="0.0055125"/>
    </inertial>
  </link>
  <joint name="ra_wrist_3_joint" type="revolute">
    <parent link="ra_wrist_2_link"/>
    <child link="ra_wrist_3_link"/>
    <origin rpy="1.57079632659 3.14159265359 3.14159265359" xyz="0 0.0922 -1.89105361091e-11"/>
    <axis xyz="0 0 1"/>
    <limit effort="54.0" lower="-6.28318530718" upper="6.28318530718" velocity="3.2"/>
    <dynamics damping="0.0" friction="0.0"/>
  </joint>
  <link name="ra_wrist_3_link">
    <visual>
      <origin rpy="1.57079632679 0 0" xyz="0 0 -0.0922"/>
      <geometry>
        <mesh filename="package://ur_description/meshes/ur10/visual/wrist3.dae"/>
      </geometry>
      <material name="LightGrey">
        <color rgba="0.7 0.7 0.7 1.0"/>
      </material>
    </visual>
    <collision>
      <origin rpy="1.57079632679 0 0" xyz="0 0 -0.0922"/>
      <geometry>
        <mesh filename="package://ur_description/meshes/ur10/collision/wrist3.stl"/>
      </geometry>
    </collision>
    <inertial>
      <mass value="0.202"/>
      <origin rpy="0 0 0" xyz="0.0 0.0 -0.01525"/>
      <inertia ixx="0.000117921661165" ixy="0.0" ixz="0.0" iyy="0.000117921661165" iyz="0.0" izz="0.000204525"/>
    </inertial>
  </link>
  <joint name="ra_ee_fixed_joint" type="fixed">
    <parent link="ra_wrist_3_link"/>
    <child link="ra_flange"/>
    <origin rpy="0.0 -1.57079632679 1.57079632679" xyz="0.0 0.0 0.0"/>
  </joint>
  <link name="ra_flange">
    <collision>
      <geometry>
        <box size="0.01 0.01 0.01"/>
      </geometry>
      <origin rpy="0 0 0" xyz="-0.01 0 0"/>
    </collision>
  </link>
  <joint name="ra_wrist_3_passive_joint" type="fixed">
    <origin rpy="0 0 0" xyz="0 0 0"/>
    <parent link="ra_wrist_3_link"/>
    <child link="ra_tool0"/>
  </joint>
  <transmission name="ra_shoulder_pan_trans">
    <type>transmission_interface/SimpleTransmission</type>
    <joint name="ra_shoulder_pan_joint">
      <hardwareInterface>hardware_interface/PositionJointInterface</hardwareInterface>
    </joint>
    <actuator name="ra_shoulder_pan_motor">
      <mechanicalReduction>1</mechanicalReduction>
    </actuator>
  </transmission>
  <transmission name="ra_shoulder_lift_trans">
    <type>transmission_interface/SimpleTransmission</type>
    <joint name="ra_shoulder_lift_joint">
      <hardwareInterface>hardware_interface/PositionJointInterface</hardwareInterface>
    </joint>
    <actuator name="ra_shoulder_lift_motor">
      <mechanicalReduction>1</mechanicalReduction>
    </actuator>
  </transmission>
  <transmission name="ra_elbow_trans">
    <type>transmission_interface/SimpleTransmission</type>
    <joint name="ra_elbow_joint">
      <hardwareInterface>hardware_interface/PositionJointInterface</hardwareInterface>
    </joint>
    <actuator name="ra_elbow_motor">
      <mechanicalReduction>1</mechanicalReduction>
    </actuator>
  </transmission>
  <transmission name="ra_wrist_1_trans">
    <type>transmission_interface/SimpleTransmission</type>
    <joint name="ra_wrist_1_joint">
      <hardwareInterface>hardware_interface/PositionJointInterface</hardwareInterface>
    </joint>
    <actuator name="ra_wrist_1_motor">
      <mechanicalReduction>1</mechanicalReduction>
    </actuator>
  </transmission>
  <transmission name="ra_wrist_2_trans">
    <type>transmission_interface/SimpleTransmission</type>
    <joint name="ra_wrist_2_joint">
      <hardwareInterface>hardware_interface/PositionJointInterface</hardwareInterface>
    </joint>
    <actuator name="ra_wrist_2_motor">
      <mechanicalReduction>1</mechanicalReduction>
    </actuator>
  </transmission>
  <transmission name="ra_wrist_3_trans">
    <type>transmission_interface/SimpleTransmission</type>
    <joint name="ra_wrist_3_joint">
      <hardwareInterface>hardware_interface/PositionJointInterface</hardwareInterface>
    </joint>
    <actuator name="ra_wrist_3_motor">
      <mechanicalReduction>1</mechanicalReduction>
    </actuator>
  </transmission>
  <gazebo reference="ra_shoulder_link">
    <selfCollide>true</selfCollide>
  </gazebo>
  <gazebo reference="ra_upper_arm_link">
    <selfCollide>true</selfCollide>
  </gazebo>
  <gazebo reference="ra_forearm_link">
    <selfCollide>true</selfCollide>
  </gazebo>
  <gazebo reference="ra_wrist_1_link">
    <selfCollide>true</selfCollide>
  </gazebo>
  <gazebo reference="ra_wrist_3_link">
    <selfCollide>true</selfCollide>
  </gazebo>
  <gazebo reference="ra_wrist_2_link">
    <selfCollide>true</selfCollide>
  </gazebo>
  <gazebo reference="ra_flange">
    <selfCollide>true</selfCollide>
  </gazebo>
  <!-- ROS base_link to UR 'Base' Coordinates transform -->
  <link name="ra_base"/>
  <joint name="ra_base_link-base_fixed_joint" type="fixed">
    <origin rpy="0 0 -3.14159265359" xyz="0 0 0"/>
    <parent link="ra_base_link"/>
    <child link="ra_base"/>
  </joint>
  <!-- Frame coincident with all-zeros TCP on UR controller -->
  <link name="ra_tool0"/>
  <gazebo>
    <plugin filename="libgazebo_ros_control.so" name="gazebo_ros_control">
      <robotSimType>sr_gazebo_sim/SrGazeboHWSim</robotSimType>
    </plugin>
  </gazebo>
  <!-- Join arm and world -->
  <link name="world"/>
  <joint name="world_joint" type="fixed">
    <parent link="world"/>
    <child link="ra_base_link"/>
    <origin rpy="0.0 0.0 0.0" xyz="0.0 0.0 0.1"/>
  </joint>
</robot>

